Workbook
Name COVERAGE: Tables!$T$3:$U$17
Name ITEMS: 'Item Builder'!$A$4:$FH$251
Name LAYERS: Tables!$AB$3:$AC$13
Name MATERIAL: Tables!$B$3:$N$36
Name MWS: Tables!$W$3:$Z$8

Sheet Standard Suits
C1: HMK page 113 | L1: HMK page 114 | U1: HMK page 115 | AD1: HMK page 116
B2: Suit Name: | C2: Light Clothing | K2: Suit Name: | L2: Kûrbúl Cuirass | T2: Suit Name: | U2: Gambeson | AC2: Suit Name: | AD2: Mail Hauberk
B3: Item List | C3: Suit is NOT LEGAL!! | K3: Item List | T3: Item List | AC3: Item List
A4: 0 | B4: Buckram Vest | C4: Price | D4: ENC | E4: PER | F4: Area | G4: LB | J4: 0 | K4: Plate Helm | L4: Price | M4: ENC | N4: PER | O4: Area | P4: LB | S4: 0 | T4: Plate Helm | U4: Price | V4: ENC | W4: PER | X4: Area | Y4: LB | AB4: 0 | AC4: Mail Cowl | AD4: Price | AE4: ENC | AF4: PER | AG4: Area | AH4: LB
A5: 0 | B5: Buckram Tunic | C5: 115 | D5: 0 | E5: 0 | F5: 1 | G5: 5.75 | J5: 0 | K5: Padded Cap | L5: 487 | M5: 5 | N5: 0 | O5: 4 | P5: 25.65 | S5: 0 | T5: Padded Cap | U5: 811 | V5: 10 | W5: 0 | X5: 5 | Y5: 30.69 | AB5: 0 | AC5: Padded Cowl | AD5: 2014 | AE5: 25 | AF5: 10 | AG5: 6 | AH5: 62.08
A6: 0 | B6: Buckram Breeches | J6: 0 | K6: Kûrbúl Spaulders | S6: 0 | T6: Gambeson Coat | AB6: 0 | AC6: Plate Coudes
A7: 0 | B7: Buckram Swaddle | C7: Loc | D7: B | E7: E | F7: P | G7: F | J7: 0 | K7: Kûrbúl Rerebraces | L7: Loc | M7: B | N7: E | O7: P | P7: F | S7: 0 | T7: Buckram Vest | U7: Loc | V7: B | W7: E | X7: P | Y7: F | AB7: 0 | AC7: Mail Mittens | AD7: Loc | AE7: B | AF7: E | AG7: P | AH7: F
A8: 0 | C8: Sk | D8: 0 | E8: 0 | F8: 0 | G8: 0 | H8: 0 | J8: 0 | K8: Kûrbúl Cuirass | L8: Sk | M8: 8 | N8: 13 | O8: 10 | P8: 7 | Q8: 4 | S8: 0 | T8: Kûrbúl Kneecops | U8: Sk | V8: 8 | W8: 13 | X8: 10 | Y8: 7 | Z8: 4 | AB8: 0 | AC8: Padded Mittens | AD8: Sk | AE8: 4 | AF8: 10 | AG8: 8 | AH8: 5 | AI8: 3
A9: 0 | C9: Fa | D9: 0 | E9: 0 | F9: 0 | G9: 0 | H9: 0 | J9: 0 | K9: Padded Tunic, Sleeved | L9: Fa | M9: 0 | N9: 0 | O9: 0 | P9: 0 | Q9: 0 | S9: 0 | T9: Padded Cuisses | U9: Fa | V9: 0 | W9: 0 | X9: 0 | Y9: 0 | Z9: 0 | AB9: 0 | AC9: Mail Hauberk | AD9: Fa | AE9: 0 | AF9: 0 | AG9: 0 | AH9: 0 | AI9: 0
A10: 0 | C10: Nk | D10: 0 | E10: 0 | F10: 0 | G10: 0 | H10: 0 | J10: 0 | K10: Buckram Trousers | L10: Nk | M10: 0 | N10: 0 | O10: 0 | P10: 0 | Q10: 0 | S10: 0 | T10: Buckram Breeches | U10: Nk | V10: 6 | W10: 5 | X10: 4 | Y10: 5 | Z10: 1 | AB10: 0 | AC10: Padded Coat | AD10: Nk | AE10: 4 | AF10: 10 | AG10: 8 | AH10: 5 | AI10: 3
A11: 0 | C11: Sh | D11: 0 | E11: 1 | F11: 0 | G11: 1 | H11: 0 | J11: 0 | K11: Buckram Swaddle | L11: Sh | M11: 6 | N11: 8 | O11: 6 | P11: 6 | Q11: 2 | S11: 0 | T11: Buckram Swaddle | U11: Sh | V11: 6 | W11: 5 | X11: 4 | Y11: 5 | Z11: 1 | AB11: 0 | AC11: Buckram Breeches | AD11: Sh | AE11: 4 | AF11: 10 | AG11: 8 | AH11: 5 | AI11: 3
A12: 0 | C12: Ua | D12: 0 | E12: 1 | F12: 0 | G12: 1 | H12: 0 | J12: 0 | K12: Leather Boots | L12: Ua | M12: 6 | N12: 8 | O12: 6 | P12: 6 | Q12: 2 | S12: 0 | T12: Leather Boots | U12: Ua | V12: 6 | W12: 5 | X12: 4 | Y12: 5 | Z12: 1 | AB12: 0 | AC12: Plate Kneecops | AD12: Ua | AE12: 4 | AF12: 10 | AG12: 8 | AH12: 5 | AI12: 3
A13: 0 | C13: El | D13: 0 | E13: 1 | F13: 0 | G13: 1 | H13: 0 | J13: 0 | L13: El | M13: 2 | N13: 2 | O13: 1 | P13: 2 | Q13: 0 | S13: 0 | U13: El | V13: 6 | W13: 5 | X13: 4 | Y13: 5 | Z13: 1 | AB13: 0 | AC13: Mail Leggings | AD13: El | AE13: 10 | AF13: 21 | AG13: 17 | AH13: 10 | AI13: 4
A14: 0 | C14: Fo | D14: 0 | E14: 0 | F14: 0 | G14: 0 | H14: 0 | J14: 0 | L14: Fo | M14: 2 | N14: 2 | O14: 1 | P14: 2 | Q14: 0 | S14: 0 | U14: Fo | V14: 6 | W14: 5 | X14: 4 | Y14: 5 | Z14: 1 | AB14: 0 | AC14: Padded Leggings | AD14: Fo | AE14: 4 | AF14: 10 | AG14: 8 | AH14: 5 | AI14: 3
A15: 0 | C15: Ha | D15: 0 | E15: 0 | F15: 0 | G15: 0 | H15: 0 | J15: 0 | L15: Ha | M15: 0 | N15: 0 | O15: 0 | P15: 0 | Q15: 0 | S15: 0 | U15: Ha | V15: 0 | W15: 0 | X15: 0 | Y15: 0 | Z15: 0 | AB15: 0 | AD15: Ha | AE15: 4 | AF15: 10 | AG15: 8 | AH15: 5 | AI15: 3
A16: 0 | C16: Tx | D16: 0 | E16: 2 | F16: 0 | G16: 2 | H16: 0 | J16: 0 | L16: Tx | M16: 6 | N16: 8 | O16: 6 | P16: 6 | Q16: 2 | S16: 0 | U16: Tx | V16: 6 | W16: 6 | X16: 4 | Y16: 6 | Z16: 1 | AB16: 0 | AD16: Tx | AE16: 4 | AF16: 10 | AG16: 8 | AH16: 5 | AI16: 3
A17: 0 | C17: Ab | D17: 0 | E17: 2 | F17: 0 | G17: 2 | H17: 0 | J17: 0 | L17: Ab | M17: 6 | N17: 8 | O17: 6 | P17: 6 | Q17: 2 | S17: 0 | U17: Ab | V17: 6 | W17: 6 | X17: 4 | Y17: 6 | Z17: 1 | AB17: 0 | AD17: Ab | AE17: 4 | AF17: 10 | AG17: 8 | AH17: 5 | AI17: 3
A18: 0 | C18: Pv | D18: 0 | E18: 2 | F18: 0 | G18: 2 | H18: 0 | J18: 0 | L18: Pv | M18: 2 | N18: 3 | O18: 1 | P18: 3 | Q18: 0 | S18: 0 | U18: Pv | V18: 6 | W18: 6 | X18: 4 | Y18: 6 | Z18: 1 | AB18: 0 | AD18: Pv | AE18: 4 | AF18: 11 | AG18: 8 | AH18: 6 | AI18: 3
A19: 0 | C19: Th | D19: 0 | E19: 1 | F19: 0 | G19: 1 | H19: 0 | J19: 0 | L19: Th | M19: 0 | N19: 1 | O19: 0 | P19: 1 | Q19: 0 | S19: 0 | U19: Th | V19: 8 | W19: 8 | X19: 5 | Y19: 8 | Z19: 1 | AB19: 0 | AD19: Th | AE19: 8 | AF19: 21 | AG19: 16 | AH19: 11 | AI19: 3
A20: 0 | C20: Kn | D20: 0 | E20: 1 | F20: 0 | G20: 1 | H20: 0 | J20: 0 | L20: Kn | M20: 0 | N20: 1 | O20: 0 | P20: 1 | Q20: 0 | S20: 0 | U20: Kn | V20: 6 | W20: 9 | X20: 6 | Y20: 7 | Z20: 2 | AB20: 0 | AD20: Kn | AE20: 10 | AF20: 22 | AG20: 17 | AH20: 11 | AI20: 4
A21: 0 | C21: Cf | D21: 0 | E21: 1 | F21: 0 | G21: 1 | H21: 0 | J21: 0 | L21: Cf | M21: 1 | N21: 4 | O21: 1 | P21: 5 | Q21: 0 | S21: 0 | U21: Cf | V21: 1 | W21: 3 | X21: 1 | Y21: 4 | Z21: 0 | AB21: 0 | AD21: Cf | AE21: 4 | AF21: 10 | AG21: 8 | AH21: 5 | AI21: 3
A22: 0 | C22: Ft | D22: 0 | E22: 1 | F22: 0 | G22: 1 | H22: 0 | J22: 0 | L22: Ft | M22: 1 | N22: 3 | O22: 1 | P22: 4 | Q22: 0 | S22: 0 | U22: Ft | V22: 1 | W22: 3 | X22: 1 | Y22: 4 | Z22: 0 | AB22: 0 | AD22: Ft | AE22: 4 | AF22: 10 | AG22: 8 | AH22: 5 | AI22: 3
A23: 0 | J23: 0 | S23: 0 | AB23: 0
A24: 0 | D24: Bulk Penalty: | J24: 0 | M24: Bulk Penalty: | S24: 0 | V24: Bulk Penalty: | AB24: 0 | AE24: Bulk Penalty:
A25: 0 | D25: Head | E25: 0 | J25: 0 | M25: Head | N25: 0 | S25: 0 | V25: Head | W25: 0 | AB25: 0 | AE25: Head | AF25: 0
A26: 0 | D26: Arms | E26: 0 | J26: 0 | M26: Arms | N26: 0 | S26: 0 | V26: Arms | W26: 0 | AB26: 0 | AE26: Arms | AF26: 0
A27: 0 | D27: Torso | E27: 0 | J27: 0 | M27: Torso | N27: 0 | S27: 0 | V27: Torso | W27: 0 | AB27: 0 | AE27: Torso | AF27: 0
A28: 0 | D28: Legs | E28: 0 | J28: 0 | M28: Legs | N28: 0 | S28: 0 | V28: Legs | W28: 0 | AB28: 0 | AE28: Legs | AF28: 0
A29: 0 | J29: 0 | S29: 0 | AB29: 0
A30: 0 | J30: 0 | S30: 0 | AB30: 0
A31: 0 | J31: 0 | S31: 0 | AB31: 0
B35: Suit Name: | C35: Heavy Clothing | K35: Suit Name: | L35: Scale Byrnie | T35: Suit Name: | U35: Scale Habergeoun | AC35: Suit Name: | AD35: Kûrbúl & Mail
B36: Item List | K36: Item List | T36: Item List | AC36: Item List
A37: 0 | B37: Leather Cap | C37: Price | D37: ENC | E37: PER | F37: Area | G37: LB | J37: 0 | K37: Plate Helm | L37: Price | M37: ENC | N37: PER | O37: Area | P37: LB | S37: 0 | T37: Plate 3/4-Helm | U37: Price | V37: ENC | W37: PER | X37: Area | Y37: LB | AB37: 0 | AC37: Plate 3/4-Helm | AD37: Price | AE37: ENC | AF37: PER | AG37: Area | AH37: LB
A38: 0 | B38: Padded Shirt | C38: 260 | D38: 0 | E38: 0 | F38: 2 | G38: 11.79 | J38: 0 | K38: Padded Cap | L38: 680 | M38: 10 | N38: 0 | O38: 4 | P38: 32.38 | S38: 0 | T38: Padded Cap | U38: 961 | V38: 15 | W38: 5 | X38: 6 | Y38: 46.38 | AB38: 0 | AC38: Mail Cowl | AD38: 2484 | AE38: 40 | AF38: 15 | AG38: 8 | AH38: 84.5
A39: 0 | B39: Buckram Tunic, Sleeved | J39: 0 | K39: Scale Byrnie | S39: 0 | T39: Kûrbúl Spaulders | AB39: 0 | AC39: Padded Cowl
A40: 0 | B40: Buckram Surcoat | C40: Loc | D40: B | E40: E | F40: P | G40: F | J40: 0 | K40: Padded Coat | L40: Loc | M40: B | N40: E | O40: P | P40: F | S40: 0 | T40: Kûrbúl Coudes | U40: Loc | V40: B | W40: E | X40: P | Y40: F | AB40: 0 | AC40: Kûrbúl Spaulders | AD40: Loc | AE40: B | AF40: E | AG40: P | AH40: F
A41: 0 | B41: Buckram Breeches | C41: Sk | D41: 1 | E41: 2 | F41: 1 | G41: 3 | H41: 2 | J41: 0 | K41: Buckram Trousers | L41: Sk | M41: 8 | N41: 13 | O41: 10 | P41: 7 | Q41: 4 | S41: 0 | T41: Leather Gauntlets | U41: Sk | V41: 8 | W41: 13 | X41: 10 | Y41: 7 | Z41: 4 | AB41: 0 | AC41: Kûrbúl Rerebraces | AD41: Sk | AE41: 10 | AF41: 21 | AG41: 17 | AH41: 10 | AI41: 3
A42: 0 | B42: Buckram Swaddle | C42: Fa | D42: 0 | E42: 0 | F42: 0 | G42: 0 | H42: 0 | J42: 0 | K42: Buckram Swaddle | L42: Fa | M42: 0 | N42: 0 | O42: 0 | P42: 0 | Q42: 0 | S42: 0 | T42: Scale Habergeoun | U42: Fa | V42: 6 | W42: 11 | X42: 9 | Y42: 5 | Z42: 0 | AB42: 0 | AC42: Kûrbúl Coudes | AD42: Fa | AE42: 6 | AF42: 11 | AG42: 9 | AH42: 5 | AI42: 0
A43: 0 | B43: Leather Shoes | C43: Nk | D43: 0 | E43: 0 | F43: 0 | G43: 0 | H43: 0 | J43: 0 | K43: Leather Boots | L43: Nk | M43: 0 | N43: 0 | O43: 0 | P43: 0 | Q43: 0 | S43: 0 | T43: Padded Coat | U43: Nk | V43: 0 | W43: 0 | X43: 0 | Y43: 0 | Z43: 0 | AB43: 0 | AC43: Mail Mittens | AD43: Nk | AE43: 4 | AF43: 10 | AG43: 8 | AH43: 5 | AI43: 3
...

Sheet Suit Builder
A1: HârnMaster Kèthîra Armour Calculator | Y1: =SUM(Y5:Y32) -> 486 | Z1: =SUM(Z5:Z32) -> 24.63 | AA1: =SUM(AA5:AA32)+IF(EA30>2,5,0) -> 5 | AB1: =SUM(AB5:AB32) -> 0 | AC1: =SUM(AC5:AC32) -> 6 | AD1: =SUM(AD5:AD32) -> 0 | AE1: =SUM(AE5:AE32) -> 0 | AF1: =SUM(AF5:AF32) -> 4 | AG1: =SUM(AG5:AG32) -> 4 | AH1: =SUM(AH5:AH32) -> 4 | AI1: =SUM(AI5:AI32) -> 4 | ... CJ1: =SUM(CJ5:CJ32) -> 4 | CK1: 0.04 | CL1: 0.03 | CM1: 0.02 | CN1: 0.03 | CO1: 0.06 | CP1: 0.02 | CQ1: 0.05 | CR1: 0.05 | CS1: 0.12 | CT1: 0.12 | CU1: 0.1 | CV1: 0.14 | CW1: 0.03 | CX1: 0.12 | CY1: 0.07
J2: 2 | K2: 3 | L2: 4 | M2: 5 | N2: 6 | O2: 7 | P2: 8 | Q2: 9 | R2: 10 | S2: 11 | T2: 12 | U2: 13 | V2: 14 | W2: 15 | X2: 16 | AC2: B | AR2: E | BG2: P | BV2: F | CK2: Layers | CZ2: Types | DO2: Layers by Type | EF2: Rigidity | EU2: 149
B3: Suit Name: | C3: Test Suit | J3: Head | M3: Arms | R3: Torso | U3: Legs | AC3: Head | AF3: Arms | AK3: Torso | AN3: Legs | AR3: Head | AU3: Arms | AZ3: Torso | BC3: Legs | BG3: Head | BJ3: Arms | BO3: Torso | BR3: Legs | BV3: Head | BY3: Arms | CD3: Torso | CG3: Legs | CK3: Head | CN3: Arms | CS3: Torso | CV3: Legs | CZ3: Head | DC3: Arms | DH3: Torso | DK3: Legs | DO3: Head | DR3: Arms | DW3: Torso | DZ3: Legs | EF3: Head | EI3: Arms | EN3: Torso | EQ3: Legs | EX3: Green areas may be edited to create new armour suits.
B4: Item List | C4: Suit is NOT LEGAL!! | J4: Sk | K4: Fa | L4: Nk | M4: Sh | N4: Ua | O4: El | P4: Fo | Q4: Ha | R4: Tx | S4: Ab | T4: Pv | U4: Th | V4: Kn | W4: Cf | X4: Ft | Y4: Price | Z4: Weight | AA4: ENC | AB4: PER | AC4: Sk | AD4: Fa | AE4: Nk | AF4: Sh | AG4: Ua | AH4: El | AI4: Fo | AJ4: Ha | AK4: Tx | AL4: Ab | AM4: Pv | AN4: Th | AO4: Kn | AP4: Cf | AQ4: Ft | AR4: Sk | AS4: Fa | AT4: Nk | AU4: Sh | AV4: Ua | AW4: El | AX4: Fo | AY4: Ha | AZ4: Tx | BA4: Ab | BB4: Pv | BC4: Th | BD4: Kn | BE4: Cf | BF4: Ft | BG4: Sk | BH4: Fa | BI4: Nk | BJ4: Sh | BK4: Ua | BL4: El | BM4: Fo | BN4: Ha | BO4: Tx | BP4: Ab | BQ4: Pv | BR4: Th | BS4: Kn | BT4: Cf | BU4: Ft | BV4: Sk | BW4: Fa | BX4: Nk | BY4: Sh | BZ4: Ua | CA4: El | CB4: Fo | CC4: Ha | CD4: Tx | CE4: Ab | CF4: Pv | CG4: Th | CH4: Kn | CI4: Cf | CJ4: Ft | CK4: Sk | CL4: Fa | CM4: Nk | CN4: Sh | CO4: Ua | CP4: El | CQ4: Fo | CR4: Ha | CS4: Tx | CT4: Ab | CU4: Pv | CV4: Th | CW4: Kn | CX4: Cf | CY4: Ft | CZ4: Sk | DA4: Fa | DB4: Nk | DC4: Sh | DD4: Ua | DE4: El | DF4: Fo | DG4: Ha | DH4: Tx | DI4: Ab | DJ4: Pv | DK4: Th | DL4: Kn | DM4: Cf | DN4: Ft | DO4: Sk | DP4: Fa | DQ4: Nk | DR4: Sh | DS4: Ua | DT4: El | DU4: Fo | DV4: Ha | DW4: Tx | DX4: Ab | DY4: Pv | DZ4: Th | EA4: Kn | EB4: Cf | EC4: Ft | EF4: Sk | EG4: Fa | EH4: Nk | EI4: Sh | EJ4: Ua | EK4: El | EL4: Fo | EM4: Ha | EN4: Tx | EO4: Ab | EP4: Pv | EQ4: Th | ER4: Kn | ES4: Cf | ET4: Ft | EU4: MWS | EV4: AQ | EW4: AV | EX4: The item list is limited to items in the Item Builder sheet,; a drop-down is provided for convenience.
A5: =EV5 -> 0 | B5: Kûrbúl Helm | C5: Price | D5: ENC | E5: PER | F5: Area | G5: LB | J5: =IF($B5="",0,VLOOKUP($B5,ITEMS,J$2,FALSE())) -> K | K5: =IF($B5="",0,VLOOKUP($B5,ITEMS,K$2,FALSE())) -> 0 | L5: =IF($B5="",0,VLOOKUP($B5,ITEMS,L$2,FALSE())) -> 0 | M5: =IF($B5="",0,VLOOKUP($B5,ITEMS,M$2,FALSE())) -> 0 | N5: =IF($B5="",0,VLOOKUP($B5,ITEMS,N$2,FALSE())) -> 0 | O5: =IF($B5="",0,VLOOKUP($B5,ITEMS,O$2,FALSE())) -> 0 | P5: =IF($B5="",0,VLOOKUP($B5,ITEMS,P$2,FALSE())) -> 0 | Q5: =IF($B5="",0,VLOOKUP($B5,ITEMS,Q$2,FALSE())) -> 0 | ... X5: =IF($B5="",0,VLOOKUP($B5,ITEMS,X$2,FALSE())) -> 0 | Y5: =IF($B5="",0,VLOOKUP($B5,ITEMS,17,FALSE())) -> 20 | Z5: =IF($B5="",0,VLOOKUP($B5,ITEMS,18,FALSE())) -> 3.04 | AA5: =IF($B5="",0,VLOOKUP($B5,ITEMS,19,FALSE())) -> 0 | AB5: =IF($B5="",0,VLOOKUP($B5,ITEMS,20,FALSE())) -> 0 | AC5: =VLOOKUP(J5,MATERIAL,5,FALSE())+IF(J5=0,0,$EW5) -> 4 | AD5: =VLOOKUP(K5,MATERIAL,5,FALSE())+IF(K5=0,0,$EW5) -> 0 | AE5: =VLOOKUP(L5,MATERIAL,5,FALSE())+IF(L5=0,0,$EW5) -> 0 | AF5: =VLOOKUP(M5,MATERIAL,5,FALSE())+IF(M5=0,0,$EW5) -> 0 | AG5: =VLOOKUP(N5,MATERIAL,5,FALSE())+IF(N5=0,0,$EW5) -> 0 | AH5: =VLOOKUP(O5,MATERIAL,5,FALSE())+IF(O5=0,0,$EW5) -> 0 | AI5: =VLOOKUP(P5,MATERIAL,5,FALSE())+IF(P5=0,0,$EW5) -> 0 | AJ5: =VLOOKUP(Q5,MATERIAL,5,FALSE())+IF(Q5=0,0,$EW5) -> 0 | ... AQ5: =VLOOKUP(X5,MATERIAL,5,FALSE())+IF(X5=0,0,$EW5) -> 0 | AR5: =VLOOKUP(J5,MATERIAL,6,FALSE())+IF(J5=0,0,$EW5) -> 6 | AS5: =VLOOKUP(K5,MATERIAL,6,FALSE())+IF(K5=0,0,$EW5) -> 0 | AT5: =VLOOKUP(L5,MATERIAL,6,FALSE())+IF(L5=0,0,$EW5) -> 0 | AU5: =VLOOKUP(M5,MATERIAL,6,FALSE())+IF(M5=0,0,$EW5) -> 0 | AV5: =VLOOKUP(N5,MATERIAL,6,FALSE())+IF(N5=0,0,$EW5) -> 0 | AW5: =VLOOKUP(O5,MATERIAL,6,FALSE())+IF(O5=0,0,$EW5) -> 0 | AX5: =VLOOKUP(P5,MATERIAL,6,FALSE())+IF(P5=0,0,$EW5) -> 0 | AY5: =VLOOKUP(Q5,MATERIAL,6,FALSE())+IF(Q5=0,0,$EW5) -> 0 | ... BF5: =VLOOKUP(X5,MATERIAL,6,FALSE())+IF(X5=0,0,$EW5) -> 0 | BG5: =VLOOKUP(J5,MATERIAL,7,FALSE())+IF(J5=0,0,$EW5) -> 5 | BH5: =VLOOKUP(K5,MATERIAL,7,FALSE())+IF(K5=0,0,$EW5) -> 0 | BI5: =VLOOKUP(L5,MATERIAL,7,FALSE())+IF(L5=0,0,$EW5) -> 0 | BJ5: =VLOOKUP(M5,MATERIAL,7,FALSE())+IF(M5=0,0,$EW5) -> 0 | BK5: =VLOOKUP(N5,MATERIAL,7,FALSE())+IF(N5=0,0,$EW5) -> 0 | BL5: =VLOOKUP(O5,MATERIAL,7,FALSE())+IF(O5=0,0,$EW5) -> 0 | BM5: =VLOOKUP(P5,MATERIAL,7,FALSE())+IF(P5=0,0,$EW5) -> 0 | BN5: =VLOOKUP(Q5,MATERIAL,7,FALSE())+IF(Q5=0,0,$EW5) -> 0 | ... BU5: =VLOOKUP(X5,MATERIAL,7,FALSE())+IF(X5=0,0,$EW5) -> 0 | BV5: =VLOOKUP(J5,MATERIAL,8,FALSE())+IF(J5=0,0,$EW5) -> 4 | BW5: =VLOOKUP(K5,MATERIAL,8,FALSE())+IF(K5=0,0,$EW5) -> 0 | BX5: =VLOOKUP(L5,MATERIAL,8,FALSE())+IF(L5=0,0,$EW5) -> 0 | BY5: =VLOOKUP(M5,MATERIAL,8,FALSE())+IF(M5=0,0,$EW5) -> 0 | BZ5: =VLOOKUP(N5,MATERIAL,8,FALSE())+IF(N5=0,0,$EW5) -> 0 | CA5: =VLOOKUP(O5,MATERIAL,8,FALSE())+IF(O5=0,0,$EW5) -> 0 | CB5: =VLOOKUP(P5,MATERIAL,8,FALSE())+IF(P5=0,0,$EW5) -> 0 | CC5: =VLOOKUP(Q5,MATERIAL,8,FALSE())+IF(Q5=0,0,$EW5) -> 0 | ... CJ5: =VLOOKUP(X5,MATERIAL,8,FALSE())+IF(X5=0,0,$EW5) -> 0 | CK5: =VLOOKUP(J5,MATERIAL,4,FALSE()) -> 1 | CL5: =VLOOKUP(K5,MATERIAL,4,FALSE()) -> 0 | CM5: =VLOOKUP(L5,MATERIAL,4,FALSE()) -> 0 | CN5: =VLOOKUP(M5,MATERIAL,4,FALSE()) -> 0 | CO5: =VLOOKUP(N5,MATERIAL,4,FALSE()) -> 0 | CP5: =VLOOKUP(O5,MATERIAL,4,FALSE()) -> 0 | CQ5: =VLOOKUP(P5,MATERIAL,4,FALSE()) -> 0 | CR5: =VLOOKUP(Q5,MATERIAL,4,FALSE()) -> 0 | ... CY5: =VLOOKUP(X5,MATERIAL,4,FALSE()) -> 0 | CZ5: =IF(J5=0,0,LEFT(J5,1)) -> K | DA5: =IF(K5=0,0,LEFT(K5,1)) -> 0 | DB5: =IF(L5=0,0,LEFT(L5,1)) -> 0 | DC5: =IF(M5=0,0,LEFT(M5,1)) -> 0 | DD5: =IF(N5=0,0,LEFT(N5,1)) -> 0 | DE5: =IF(O5=0,0,LEFT(O5,1)) -> 0 | DF5: =IF(P5=0,0,LEFT(P5,1)) -> 0 | DG5: =IF(Q5=0,0,LEFT(Q5,1)) -> 0 | ... DN5: =IF(X5=0,0,LEFT(X5,1)) -> 0 | DO5: =SUMIF(CZ$5:CZ$32,$ED5,CK$5:CK$32) -> 1.5 | DP5: =SUMIF(DA$5:DA$32,$ED5,CL$5:CL$32) -> 0 | DQ5: =SUMIF(DB$5:DB$32,$ED5,CM$5:CM$32) -> 0 | DR5: =SUMIF(DC$5:DC$32,$ED5,CN$5:CN$32) -> 0 | DS5: =SUMIF(DD$5:DD$32,$ED5,CO$5:CO$32) -> 0 | DT5: =SUMIF(DE$5:DE$32,$ED5,CP$5:CP$32) -> 0 | DU5: =SUMIF(DF$5:DF$32,$ED5,CQ$5:CQ$32) -> 0 | DV5: =SUMIF(DG$5:DG$32,$ED5,CR$5:CR$32) -> 0 | ... EC5: =SUMIF(DN$5:DN$32,$ED5,CY$5:CY$32) -> 0 | ED5: D | EF5: =VLOOKUP(J5,MATERIAL,9,FALSE()) -> 2 | EG5: =VLOOKUP(K5,MATERIAL,9,FALSE()) -> 0 | EH5: =VLOOKUP(L5,MATERIAL,9,FALSE()) -> 0 | EI5: =VLOOKUP(M5,MATERIAL,9,FALSE()) -> 0 | EJ5: =VLOOKUP(N5,MATERIAL,9,FALSE()) -> 0 | EK5: =VLOOKUP(O5,MATERIAL,9,FALSE()) -> 0 | EL5: =VLOOKUP(P5,MATERIAL,9,FALSE()) -> 0 | EM5: =VLOOKUP(Q5,MATERIAL,9,FALSE()) -> 0 | ... ET5: =VLOOKUP(X5,MATERIAL,9,FALSE()) -> 0 | EU5: =IF($B5="",0,VLOOKUP($B5,ITEMS,EU$2,FALSE())) -> 0 | EV5: =VLOOKUP(EU5,MWS,2) -> 0 | EW5: =VLOOKUP(EU5,MWS,3) -> 0 | EX5: The suit name may be entered freely.
A6: =EV6 -> 0 | B6: Padded Cap | C6: =Y1 -> 486 | D6: =AA1 -> 5 | E6: =AB1 -> 0 | F6: =ROUND(SUMPRODUCT(BV1:CJ1,CK1:CY1)+0.2,0) -> 4 | G6: =Z1 -> 24.63 | J6: =IF($B6="",0,VLOOKUP($B6,ITEMS,J$2,FALSE())) -> D | K6: =IF($B6="",0,VLOOKUP($B6,ITEMS,K$2,FALSE())) -> 0 | L6: =IF($B6="",0,VLOOKUP($B6,ITEMS,L$2,FALSE())) -> 0 | M6: =IF($B6="",0,VLOOKUP($B6,ITEMS,M$2,FALSE())) -> 0 | N6: =IF($B6="",0,VLOOKUP($B6,ITEMS,N$2,FALSE())) -> 0 | O6: =IF($B6="",0,VLOOKUP($B6,ITEMS,O$2,FALSE())) -> 0 | P6: =IF($B6="",0,VLOOKUP($B6,ITEMS,P$2,FALSE())) -> 0 | Q6: =IF($B6="",0,VLOOKUP($B6,ITEMS,Q$2,FALSE())) -> 0 | ... X6: =IF($B6="",0,VLOOKUP($B6,ITEMS,X$2,FALSE())) -> 0 | Y6: =IF($B6="",0,VLOOKUP($B6,ITEMS,17,FALSE())) -> 8 | Z6: =IF($B6="",0,VLOOKUP($B6,ITEMS,18,FALSE())) -> 0.32 | AA6: =IF($B6="",0,VLOOKUP($B6,ITEMS,19,FALSE())) -> 0 | AB6: =IF($B6="",0,VLOOKUP($B6,ITEMS,20,FALSE())) -> 0 | AC6: =VLOOKUP(J6,MATERIAL,5,FALSE())+IF(J6=0,0,$EW6) -> 2 | AD6: =VLOOKUP(K6,MATERIAL,5,FALSE())+IF(K6=0,0,$EW6) -> 0 | AE6: =VLOOKUP(L6,MATERIAL,5,FALSE())+IF(L6=0,0,$EW6) -> 0 | AF6: =VLOOKUP(M6,MATERIAL,5,FALSE())+IF(M6=0,0,$EW6) -> 0 | AG6: =VLOOKUP(N6,MATERIAL,5,FALSE())+IF(N6=0,0,$EW6) -> 0 | AH6: =VLOOKUP(O6,MATERIAL,5,FALSE())+IF(O6=0,0,$EW6) -> 0 | AI6: =VLOOKUP(P6,MATERIAL,5,FALSE())+IF(P6=0,0,$EW6) -> 0 | AJ6: =VLOOKUP(Q6,MATERIAL,5,FALSE())+IF(Q6=0,0,$EW6) -> 0 | ... AQ6: =VLOOKUP(X6,MATERIAL,5,FALSE())+IF(X6=0,0,$EW6) -> 0 | AR6: =VLOOKUP(J6,MATERIAL,6,FALSE())+IF(J6=0,0,$EW6) -> 2 | AS6: =VLOOKUP(K6,MATERIAL,6,FALSE())+IF(K6=0,0,$EW6) -> 0 | AT6: =VLOOKUP(L6,MATERIAL,6,FALSE())+IF(L6=0,0,$EW6) -> 0 | AU6: =VLOOKUP(M6,MATERIAL,6,FALSE())+IF(M6=0,0,$EW6) -> 0 | AV6: =VLOOKUP(N6,MATERIAL,6,FALSE())+IF(N6=0,0,$EW6) -> 0 | AW6: =VLOOKUP(O6,MATERIAL,6,FALSE())+IF(O6=0,0,$EW6) -> 0 | AX6: =VLOOKUP(P6,MATERIAL,6,FALSE())+IF(P6=0,0,$EW6) -> 0 | AY6: =VLOOKUP(Q6,MATERIAL,6,FALSE())+IF(Q6=0,0,$EW6) -> 0 | ... BF6: =VLOOKUP(X6,MATERIAL,6,FALSE())+IF(X6=0,0,$EW6) -> 0 | BG6: =VLOOKUP(J6,MATERIAL,7,FALSE())+IF(J6=0,0,$EW6) -> 1 | BH6: =VLOOKUP(K6,MATERIAL,7,FALSE())+IF(K6=0,0,$EW6) -> 0 | BI6: =VLOOKUP(L6,MATERIAL,7,FALSE())+IF(L6=0,0,$EW6) -> 0 | BJ6: =VLOOKUP(M6,MATERIAL,7,FALSE())+IF(M6=0,0,$EW6) -> 0 | BK6: =VLOOKUP(N6,MATERIAL,7,FALSE())+IF(N6=0,0,$EW6) -> 0 | BL6: =VLOOKUP(O6,MATERIAL,7,FALSE())+IF(O6=0,0,$EW6) -> 0 | BM6: =VLOOKUP(P6,MATERIAL,7,FALSE())+IF(P6=0,0,$EW6) -> 0 | BN6: =VLOOKUP(Q6,MATERIAL,7,FALSE())+IF(Q6=0,0,$EW6) -> 0 | ... BU6: =VLOOKUP(X6,MATERIAL,7,FALSE())+IF(X6=0,0,$EW6) -> 0 | BV6: =VLOOKUP(J6,MATERIAL,8,FALSE())+IF(J6=0,0,$EW6) -> 2 | BW6: =VLOOKUP(K6,MATERIAL,8,FALSE())+IF(K6=0,0,$EW6) -> 0 | BX6: =VLOOKUP(L6,MATERIAL,8,FALSE())+IF(L6=0,0,$EW6) -> 0 | BY6: =VLOOKUP(M6,MATERIAL,8,FALSE())+IF(M6=0,0,$EW6) -> 0 | BZ6: =VLOOKUP(N6,MATERIAL,8,FALSE())+IF(N6=0,0,$EW6) -> 0 | CA6: =VLOOKUP(O6,MATERIAL,8,FALSE())+IF(O6=0,0,$EW6) -> 0 | CB6: =VLOOKUP(P6,MATERIAL,8,FALSE())+IF(P6=0,0,$EW6) -> 0 | CC6: =VLOOKUP(Q6,MATERIAL,8,FALSE())+IF(Q6=0,0,$EW6) -> 0 | ... CJ6: =VLOOKUP(X6,MATERIAL,8,FALSE())+IF(X6=0,0,$EW6) -> 0 | CK6: =VLOOKUP(J6,MATERIAL,4,FALSE()) -> 1.5 | CL6: =VLOOKUP(K6,MATERIAL,4,FALSE()) -> 0 | CM6: =VLOOKUP(L6,MATERIAL,4,FALSE()) -> 0 | CN6: =VLOOKUP(M6,MATERIAL,4,FALSE()) -> 0 | CO6: =VLOOKUP(N6,MATERIAL,4,FALSE()) -> 0 | CP6: =VLOOKUP(O6,MATERIAL,4,FALSE()) -> 0 | CQ6: =VLOOKUP(P6,MATERIAL,4,FALSE()) -> 0 | CR6: =VLOOKUP(Q6,MATERIAL,4,FALSE()) -> 0 | ... CY6: =VLOOKUP(X6,MATERIAL,4,FALSE()) -> 0 | CZ6: =IF(J6=0,0,LEFT(J6,1)) -> D | DA6: =IF(K6=0,0,LEFT(K6,1)) -> 0 | DB6: =IF(L6=0,0,LEFT(L6,1)) -> 0 | DC6: =IF(M6=0,0,LEFT(M6,1)) -> 0 | DD6: =IF(N6=0,0,LEFT(N6,1)) -> 0 | DE6: =IF(O6=0,0,LEFT(O6,1)) -> 0 | DF6: =IF(P6=0,0,LEFT(P6,1)) -> 0 | DG6: =IF(Q6=0,0,LEFT(Q6,1)) -> 0 | ... DN6: =IF(X6=0,0,LEFT(X6,1)) -> 0 | DO6: =SUMIF(CZ$5:CZ$32,$ED6,CK$5:CK$32) -> 0 | DP6: =SUMIF(DA$5:DA$32,$ED6,CL$5:CL$32) -> 0 | DQ6: =SUMIF(DB$5:DB$32,$ED6,CM$5:CM$32) -> 0 | DR6: =SUMIF(DC$5:DC$32,$ED6,CN$5:CN$32) -> 2 | DS6: =SUMIF(DD$5:DD$32,$ED6,CO$5:CO$32) -> 2 | DT6: =SUMIF(DE$5:DE$32,$ED6,CP$5:CP$32) -> 2 | DU6: =SUMIF(DF$5:DF$32,$ED6,CQ$5:CQ$32) -> 2 | DV6: =SUMIF(DG$5:DG$32,$ED6,CR$5:CR$32) -> 0 | ... EC6: =SUMIF(DN$5:DN$32,$ED6,CY$5:CY$32) -> 0 | ED6: Q | EF6: =VLOOKUP(J6,MATERIAL,9,FALSE()) -> 0 | EG6: =VLOOKUP(K6,MATERIAL,9,FALSE()) -> 0 | EH6: =VLOOKUP(L6,MATERIAL,9,FALSE()) -> 0 | EI6: =VLOOKUP(M6,MATERIAL,9,FALSE()) -> 0 | EJ6: =VLOOKUP(N6,MATERIAL,9,FALSE()) -> 0 | EK6: =VLOOKUP(O6,MATERIAL,9,FALSE()) -> 0 | EL6: =VLOOKUP(P6,MATERIAL,9,FALSE()) -> 0 | EM6: =VLOOKUP(Q6,MATERIAL,9,FALSE()) -> 0 | ... ET6: =VLOOKUP(X6,MATERIAL,9,FALSE()) -> 0 | EU6: =IF($B6="",0,VLOOKUP($B6,ITEMS,EU$2,FALSE())) -> 0 | EV6: =VLOOKUP(EU6,MWS,2) -> 0 | EW6: =VLOOKUP(EU6,MWS,3) -> 0
A7: =EV7 -> 0 | B7: Quilted Coat | J7: =IF($B7="",0,VLOOKUP($B7,ITEMS,J$2,FALSE())) -> 0 | K7: =IF($B7="",0,VLOOKUP($B7,ITEMS,K$2,FALSE())) -> 0 | L7: =IF($B7="",0,VLOOKUP($B7,ITEMS,L$2,FALSE())) -> 0 | M7: =IF($B7="",0,VLOOKUP($B7,ITEMS,M$2,FALSE())) -> Q | N7: =IF($B7="",0,VLOOKUP($B7,ITEMS,N$2,FALSE())) -> Q | O7: =IF($B7="",0,VLOOKUP($B7,ITEMS,O$2,FALSE())) -> Q | P7: =IF($B7="",0,VLOOKUP($B7,ITEMS,P$2,FALSE())) -> Q | Q7: =IF($B7="",0,VLOOKUP($B7,ITEMS,Q$2,FALSE())) -> 0 | ... X7: =IF($B7="",0,VLOOKUP($B7,ITEMS,X$2,FALSE())) -> 0 | Y7: =IF($B7="",0,VLOOKUP($B7,ITEMS,17,FALSE())) -> 256 | Z7: =IF($B7="",0,VLOOKUP($B7,ITEMS,18,FALSE())) -> 11.52 | AA7: =IF($B7="",0,VLOOKUP($B7,ITEMS,19,FALSE())) -> 5 | AB7: =IF($B7="",0,VLOOKUP($B7,ITEMS,20,FALSE())) -> 0 | AC7: =VLOOKUP(J7,MATERIAL,5,FALSE())+IF(J7=0,0,$EW7) -> 0 | AD7: =VLOOKUP(K7,MATERIAL,5,FALSE())+IF(K7=0,0,$EW7) -> 0 | AE7: =VLOOKUP(L7,MATERIAL,5,FALSE())+IF(L7=0,0,$EW7) -> 0 | AF7: =VLOOKUP(M7,MATERIAL,5,FALSE())+IF(M7=0,0,$EW7) -> 4 | AG7: =VLOOKUP(N7,MATERIAL,5,FALSE())+IF(N7=0,0,$EW7) -> 4 | AH7: =VLOOKUP(O7,MATERIAL,5,FALSE())+IF(O7=0,0,$EW7) -> 4 | AI7: =VLOOKUP(P7,MATERIAL,5,FALSE())+IF(P7=0,0,$EW7) -> 4 | AJ7: =VLOOKUP(Q7,MATERIAL,5,FALSE())+IF(Q7=0,0,$EW7) -> 0 | ... AQ7: =VLOOKUP(X7,MATERIAL,5,FALSE())+IF(X7=0,0,$EW7) -> 0 | AR7: =VLOOKUP(J7,MATERIAL,6,FALSE())+IF(J7=0,0,$EW7) -> 0 | AS7: =VLOOKUP(K7,MATERIAL,6,FALSE())+IF(K7=0,0,$EW7) -> 0 | AT7: =VLOOKUP(L7,MATERIAL,6,FALSE())+IF(L7=0,0,$EW7) -> 0 | AU7: =VLOOKUP(M7,MATERIAL,6,FALSE())+IF(M7=0,0,$EW7) -> 3 | AV7: =VLOOKUP(N7,MATERIAL,6,FALSE())+IF(N7=0,0,$EW7) -> 3 | AW7: =VLOOKUP(O7,MATERIAL,6,FALSE())+IF(O7=0,0,$EW7) -> 3 | AX7: =VLOOKUP(P7,MATERIAL,6,FALSE())+IF(P7=0,0,$EW7) -> 3 | AY7: =VLOOKUP(Q7,MATERIAL,6,FALSE())+IF(Q7=0,0,$EW7) -> 0 | ... BF7: =VLOOKUP(X7,MATERIAL,6,FALSE())+IF(X7=0,0,$EW7) -> 0 | BG7: =VLOOKUP(J7,MATERIAL,7,FALSE())+IF(J7=0,0,$EW7) -> 0 | BH7: =VLOOKUP(K7,MATERIAL,7,FALSE())+IF(K7=0,0,$EW7) -> 0 | BI7: =VLOOKUP(L7,MATERIAL,7,FALSE())+IF(L7=0,0,$EW7) -> 0 | BJ7: =VLOOKUP(M7,MATERIAL,7,FALSE())+IF(M7=0,0,$EW7) -> 2 | BK7: =VLOOKUP(N7,MATERIAL,7,FALSE())+IF(N7=0,0,$EW7) -> 2 | BL7: =VLOOKUP(O7,MATERIAL,7,FALSE())+IF(O7=0,0,$EW7) -> 2 | BM7: =VLOOKUP(P7,MATERIAL,7,FALSE())+IF(P7=0,0,$EW7) -> 2 | BN7: =VLOOKUP(Q7,MATERIAL,7,FALSE())+IF(Q7=0,0,$EW7) -> 0 | ... BU7: =VLOOKUP(X7,MATERIAL,7,FALSE())+IF(X7=0,0,$EW7) -> 0 | BV7: =VLOOKUP(J7,MATERIAL,8,FALSE())+IF(J7=0,0,$EW7) -> 0 | BW7: =VLOOKUP(K7,MATERIAL,8,FALSE())+IF(K7=0,0,$EW7) -> 0 | BX7: =VLOOKUP(L7,MATERIAL,8,FALSE())+IF(L7=0,0,$EW7) -> 0 | BY7: =VLOOKUP(M7,MATERIAL,8,FALSE())+IF(M7=0,0,$EW7) -> 3 | BZ7: =VLOOKUP(N7,MATERIAL,8,FALSE())+IF(N7=0,0,$EW7) -> 3 | CA7: =VLOOKUP(O7,MATERIAL,8,FALSE())+IF(O7=0,0,$EW7) -> 3 | CB7: =VLOOKUP(P7,MATERIAL,8,FALSE())+IF(P7=0,0,$EW7) -> 3 | CC7: =VLOOKUP(Q7,MATERIAL,8,FALSE())+IF(Q7=0,0,$EW7) -> 0 | ... CJ7: =VLOOKUP(X7,MATERIAL,8,FALSE())+IF(X7=0,0,$EW7) -> 0 | CK7: =VLOOKUP(J7,MATERIAL,4,FALSE()) -> 0 | CL7: =VLOOKUP(K7,MATERIAL,4,FALSE()) -> 0 | CM7: =VLOOKUP(L7,MATERIAL,4,FALSE()) -> 0 | CN7: =VLOOKUP(M7,MATERIAL,4,FALSE()) -> 2 | CO7: =VLOOKUP(N7,MATERIAL,4,FALSE()) -> 2 | CP7: =VLOOKUP(O7,MATERIAL,4,FALSE()) -> 2 | CQ7: =VLOOKUP(P7,MATERIAL,4,FALSE()) -> 2 | CR7: =VLOOKUP(Q7,MATERIAL,4,FALSE()) -> 0 | ... CY7: =VLOOKUP(X7,MATERIAL,4,FALSE()) -> 0 | CZ7: =IF(J7=0,0,LEFT(J7,1)) -> 0 | DA7: =IF(K7=0,0,LEFT(K7,1)) -> 0 | DB7: =IF(L7=0,0,LEFT(L7,1)) -> 0 | DC7: =IF(M7=0,0,LEFT(M7,1)) -> Q | DD7: =IF(N7=0,0,LEFT(N7,1)) -> Q | DE7: =IF(O7=0,0,LEFT(O7,1)) -> Q | DF7: =IF(P7=0,0,LEFT(P7,1)) -> Q | DG7: =IF(Q7=0,0,LEFT(Q7,1)) -> 0 | ... DN7: =IF(X7=0,0,LEFT(X7,1)) -> 0 | DO7: =SUMIF(CZ$5:CZ$32,$ED7,CK$5:CK$32) -> 0 | DP7: =SUMIF(DA$5:DA$32,$ED7,CL$5:CL$32) -> 0 | DQ7: =SUMIF(DB$5:DB$32,$ED7,CM$5:CM$32) -> 0 | DR7: =SUMIF(DC$5:DC$32,$ED7,CN$5:CN$32) -> 0 | DS7: =SUMIF(DD$5:DD$32,$ED7,CO$5:CO$32) -> 0 | DT7: =SUMIF(DE$5:DE$32,$ED7,CP$5:CP$32) -> 0 | DU7: =SUMIF(DF$5:DF$32,$ED7,CQ$5:CQ$32) -> 0 | DV7: =SUMIF(DG$5:DG$32,$ED7,CR$5:CR$32) -> 0 | ... EC7: =SUMIF(DN$5:DN$32,$ED7,CY$5:CY$32) -> 0 | ED7: G | EF7: =VLOOKUP(J7,MATERIAL,9,FALSE()) -> 0 | EG7: =VLOOKUP(K7,MATERIAL,9,FALSE()) -> 0 | EH7: =VLOOKUP(L7,MATERIAL,9,FALSE()) -> 0 | EI7: =VLOOKUP(M7,MATERIAL,9,FALSE()) -> 0 | EJ7: =VLOOKUP(N7,MATERIAL,9,FALSE()) -> 0 | EK7: =VLOOKUP(O7,MATERIAL,9,FALSE()) -> 0 | EL7: =VLOOKUP(P7,MATERIAL,9,FALSE()) -> 0 | EM7: =VLOOKUP(Q7,MATERIAL,9,FALSE()) -> 0 | ... ET7: =VLOOKUP(X7,MATERIAL,9,FALSE()) -> 0 | EU7: =IF($B7="",0,VLOOKUP($B7,ITEMS,EU$2,FALSE())) -> 0 | EV7: =VLOOKUP(EU7,MWS,2) -> 0 | EW7: =VLOOKUP(EU7,MWS,3) -> 0
A8: =EV8 -> 0 | B8: Buckram Tunic | C8: Loc | D8: B | E8: E | F8: P | G8: F | J8: =IF($B8="",0,VLOOKUP($B8,ITEMS,J$2,FALSE())) -> 0 | K8: =IF($B8="",0,VLOOKUP($B8,ITEMS,K$2,FALSE())) -> 0 | L8: =IF($B8="",0,VLOOKUP($B8,ITEMS,L$2,FALSE())) -> 0 | M8: =IF($B8="",0,VLOOKUP($B8,ITEMS,M$2,FALSE())) -> C | N8: =IF($B8="",0,VLOOKUP($B8,ITEMS,N$2,FALSE())) -> C | O8: =IF($B8="",0,VLOOKUP($B8,ITEMS,O$2,FALSE())) -> C | P8: =IF($B8="",0,VLOOKUP($B8,ITEMS,P$2,FALSE())) -> 0 | Q8: =IF($B8="",0,VLOOKUP($B8,ITEMS,Q$2,FALSE())) -> 0 | ... X8: =IF($B8="",0,VLOOKUP($B8,ITEMS,X$2,FALSE())) -> 0 | Y8: =IF($B8="",0,VLOOKUP($B8,ITEMS,17,FALSE())) -> 45 | Z8: =IF($B8="",0,VLOOKUP($B8,ITEMS,18,FALSE())) -> 2.25 | AA8: =IF($B8="",0,VLOOKUP($B8,ITEMS,19,FALSE())) -> 0 | AB8: =IF($B8="",0,VLOOKUP($B8,ITEMS,20,FALSE())) -> 0 | AC8: =VLOOKUP(J8,MATERIAL,5,FALSE())+IF(J8=0,0,$EW8) -> 0 | AD8: =VLOOKUP(K8,MATERIAL,5,FALSE())+IF(K8=0,0,$EW8) -> 0 | AE8: =VLOOKUP(L8,MATERIAL,5,FALSE())+IF(L8=0,0,$EW8) -> 0 | AF8: =VLOOKUP(M8,MATERIAL,5,FALSE())+IF(M8=0,0,$EW8) -> 0 | AG8: =VLOOKUP(N8,MATERIAL,5,FALSE())+IF(N8=0,0,$EW8) -> 0 | AH8: =VLOOKUP(O8,MATERIAL,5,FALSE())+IF(O8=0,0,$EW8) -> 0 | AI8: =VLOOKUP(P8,MATERIAL,5,FALSE())+IF(P8=0,0,$EW8) -> 0 | AJ8: =VLOOKUP(Q8,MATERIAL,5,FALSE())+IF(Q8=0,0,$EW8) -> 0 | ... AQ8: =VLOOKUP(X8,MATERIAL,5,FALSE())+IF(X8=0,0,$EW8) -> 0 | AR8: =VLOOKUP(J8,MATERIAL,6,FALSE())+IF(J8=0,0,$EW8) -> 0 | AS8: =VLOOKUP(K8,MATERIAL,6,FALSE())+IF(K8=0,0,$EW8) -> 0 | AT8: =VLOOKUP(L8,MATERIAL,6,FALSE())+IF(L8=0,0,$EW8) -> 0 | AU8: =VLOOKUP(M8,MATERIAL,6,FALSE())+IF(M8=0,0,$EW8) -> 1 | AV8: =VLOOKUP(N8,MATERIAL,6,FALSE())+IF(N8=0,0,$EW8) -> 1 | AW8: =VLOOKUP(O8,MATERIAL,6,FALSE())+IF(O8=0,0,$EW8) -> 1 | AX8: =VLOOKUP(P8,MATERIAL,6,FALSE())+IF(P8=0,0,$EW8) -> 0 | AY8: =VLOOKUP(Q8,MATERIAL,6,FALSE())+IF(Q8=0,0,$EW8) -> 0 | ... BF8: =VLOOKUP(X8,MATERIAL,6,FALSE())+IF(X8=0,0,$EW8) -> 0 | BG8: =VLOOKUP(J8,MATERIAL,7,FALSE())+IF(J8=0,0,$EW8) -> 0 | BH8: =VLOOKUP(K8,MATERIAL,7,FALSE())+IF(K8=0,0,$EW8) -> 0 | BI8: =VLOOKUP(L8,MATERIAL,7,FALSE())+IF(L8=0,0,$EW8) -> 0 | BJ8: =VLOOKUP(M8,MATERIAL,7,FALSE())+IF(M8=0,0,$EW8) -> 0 | BK8: =VLOOKUP(N8,MATERIAL,7,FALSE())+IF(N8=0,0,$EW8) -> 0 | BL8: =VLOOKUP(O8,MATERIAL,7,FALSE())+IF(O8=0,0,$EW8) -> 0 | BM8: =VLOOKUP(P8,MATERIAL,7,FALSE())+IF(P8=0,0,$EW8) -> 0 | BN8: =VLOOKUP(Q8,MATERIAL,7,FALSE())+IF(Q8=0,0,$EW8) -> 0 | ... BU8: =VLOOKUP(X8,MATERIAL,7,FALSE())+IF(X8=0,0,$EW8) -> 0 | BV8: =VLOOKUP(J8,MATERIAL,8,FALSE())+IF(J8=0,0,$EW8) -> 0 | BW8: =VLOOKUP(K8,MATERIAL,8,FALSE())+IF(K8=0,0,$EW8) -> 0 | BX8: =VLOOKUP(L8,MATERIAL,8,FALSE())+IF(L8=0,0,$EW8) -> 0 | BY8: =VLOOKUP(M8,MATERIAL,8,FALSE())+IF(M8=0,0,$EW8) -> 1 | BZ8: =VLOOKUP(N8,MATERIAL,8,FALSE())+IF(N8=0,0,$EW8) -> 1 | CA8: =VLOOKUP(O8,MATERIAL,8,FALSE())+IF(O8=0,0,$EW8) -> 1 | CB8: =VLOOKUP(P8,MATERIAL,8,FALSE())+IF(P8=0,0,$EW8) -> 0 | CC8: =VLOOKUP(Q8,MATERIAL,8,FALSE())+IF(Q8=0,0,$EW8) -> 0 | ... CJ8: =VLOOKUP(X8,MATERIAL,8,FALSE())+IF(X8=0,0,$EW8) -> 0 | CK8: =VLOOKUP(J8,MATERIAL,4,FALSE()) -> 0 | CL8: =VLOOKUP(K8,MATERIAL,4,FALSE()) -> 0 | CM8: =VLOOKUP(L8,MATERIAL,4,FALSE()) -> 0 | CN8: =VLOOKUP(M8,MATERIAL,4,FALSE()) -> 1 | CO8: =VLOOKUP(N8,MATERIAL,4,FALSE()) -> 1 | CP8: =VLOOKUP(O8,MATERIAL,4,FALSE()) -> 1 | CQ8: =VLOOKUP(P8,MATERIAL,4,FALSE()) -> 0 | CR8: =VLOOKUP(Q8,MATERIAL,4,FALSE()) -> 0 | ... CY8: =VLOOKUP(X8,MATERIAL,4,FALSE()) -> 0 | CZ8: =IF(J8=0,0,LEFT(J8,1)) -> 0 | DA8: =IF(K8=0,0,LEFT(K8,1)) -> 0 | DB8: =IF(L8=0,0,LEFT(L8,1)) -> 0 | DC8: =IF(M8=0,0,LEFT(M8,1)) -> C | DD8: =IF(N8=0,0,LEFT(N8,1)) -> C | DE8: =IF(O8=0,0,LEFT(O8,1)) -> C | DF8: =IF(P8=0,0,LEFT(P8,1)) -> 0 | DG8: =IF(Q8=0,0,LEFT(Q8,1)) -> 0 | ... DN8: =IF(X8=0,0,LEFT(X8,1)) -> 0 | DO8: =SUMIF(CZ$5:CZ$32,$ED8,CK$5:CK$32) -> 0 | DP8: =SUMIF(DA$5:DA$32,$ED8,CL$5:CL$32) -> 0 | DQ8: =SUMIF(DB$5:DB$32,$ED8,CM$5:CM$32) -> 0 | DR8: =SUMIF(DC$5:DC$32,$ED8,CN$5:CN$32) -> 0 | DS8: =SUMIF(DD$5:DD$32,$ED8,CO$5:CO$32) -> 0 | DT8: =SUMIF(DE$5:DE$32,$ED8,CP$5:CP$32) -> 0 | DU8: =SUMIF(DF$5:DF$32,$ED8,CQ$5:CQ$32) -> 0 | DV8: =SUMIF(DG$5:DG$32,$ED8,CR$5:CR$32) -> 0 | ... EC8: =SUMIF(DN$5:DN$32,$ED8,CY$5:CY$32) -> 1 | ED8: L | EF8: =VLOOKUP(J8,MATERIAL,9,FALSE()) -> 0 | EG8: =VLOOKUP(K8,MATERIAL,9,FALSE()) -> 0 | EH8: =VLOOKUP(L8,MATERIAL,9,FALSE()) -> 0 | EI8: =VLOOKUP(M8,MATERIAL,9,FALSE()) -> 0 | EJ8: =VLOOKUP(N8,MATERIAL,9,FALSE()) -> 0 | EK8: =VLOOKUP(O8,MATERIAL,9,FALSE()) -> 0 | EL8: =VLOOKUP(P8,MATERIAL,9,FALSE()) -> 0 | EM8: =VLOOKUP(Q8,MATERIAL,9,FALSE()) -> 0 | ... ET8: =VLOOKUP(X8,MATERIAL,9,FALSE()) -> 0 | EU8: =IF($B8="",0,VLOOKUP($B8,ITEMS,EU$2,FALSE())) -> 0 | EV8: =VLOOKUP(EU8,MWS,2) -> 0 | EW8: =VLOOKUP(EU8,MWS,3) -> 0
A9: =EV9 -> 0 | B9: Buckram Breeches | C9: Sk | D9: =AC1 -> 6 | E9: =AR1 -> 8 | F9: =BG1 -> 6 | G9: =BV1 -> 6 | H9: =MAX(EF5:EF32) -> 2 | J9: =IF($B9="",0,VLOOKUP($B9,ITEMS,J$2,FALSE())) -> 0 | K9: =IF($B9="",0,VLOOKUP($B9,ITEMS,K$2,FALSE())) -> 0 | L9: =IF($B9="",0,VLOOKUP($B9,ITEMS,L$2,FALSE())) -> 0 | M9: =IF($B9="",0,VLOOKUP($B9,ITEMS,M$2,FALSE())) -> 0 | N9: =IF($B9="",0,VLOOKUP($B9,ITEMS,N$2,FALSE())) -> 0 | O9: =IF($B9="",0,VLOOKUP($B9,ITEMS,O$2,FALSE())) -> 0 | P9: =IF($B9="",0,VLOOKUP($B9,ITEMS,P$2,FALSE())) -> 0 | Q9: =IF($B9="",0,VLOOKUP($B9,ITEMS,Q$2,FALSE())) -> 0 | ... X9: =IF($B9="",0,VLOOKUP($B9,ITEMS,X$2,FALSE())) -> 0 | Y9: =IF($B9="",0,VLOOKUP($B9,ITEMS,17,FALSE())) -> 27 | Z9: =IF($B9="",0,VLOOKUP($B9,ITEMS,18,FALSE())) -> 1.35 | AA9: =IF($B9="",0,VLOOKUP($B9,ITEMS,19,FALSE())) -> 0 | AB9: =IF($B9="",0,VLOOKUP($B9,ITEMS,20,FALSE())) -> 0 | AC9: =VLOOKUP(J9,MATERIAL,5,FALSE())+IF(J9=0,0,$EW9) -> 0 | AD9: =VLOOKUP(K9,MATERIAL,5,FALSE())+IF(K9=0,0,$EW9) -> 0 | AE9: =VLOOKUP(L9,MATERIAL,5,FALSE())+IF(L9=0,0,$EW9) -> 0 | AF9: =VLOOKUP(M9,MATERIAL,5,FALSE())+IF(M9=0,0,$EW9) -> 0 | AG9: =VLOOKUP(N9,MATERIAL,5,FALSE())+IF(N9=0,0,$EW9) -> 0 | AH9: =VLOOKUP(O9,MATERIAL,5,FALSE())+IF(O9=0,0,$EW9) -> 0 | AI9: =VLOOKUP(P9,MATERIAL,5,FALSE())+IF(P9=0,0,$EW9) -> 0 | AJ9: =VLOOKUP(Q9,MATERIAL,5,FALSE())+IF(Q9=0,0,$EW9) -> 0 | ... AQ9: =VLOOKUP(X9,MATERIAL,5,FALSE())+IF(X9=0,0,$EW9) -> 0 | AR9: =VLOOKUP(J9,MATERIAL,6,FALSE())+IF(J9=0,0,$EW9) -> 0 | AS9: =VLOOKUP(K9,MATERIAL,6,FALSE())+IF(K9=0,0,$EW9) -> 0 | AT9: =VLOOKUP(L9,MATERIAL,6,FALSE())+IF(L9=0,0,$EW9) -> 0 | AU9: =VLOOKUP(M9,MATERIAL,6,FALSE())+IF(M9=0,0,$EW9) -> 0 | AV9: =VLOOKUP(N9,MATERIAL,6,FALSE())+IF(N9=0,0,$EW9) -> 0 | AW9: =VLOOKUP(O9,MATERIAL,6,FALSE())+IF(O9=0,0,$EW9) -> 0 | AX9: =VLOOKUP(P9,MATERIAL,6,FALSE())+IF(P9=0,0,$EW9) -> 0 | AY9: =VLOOKUP(Q9,MATERIAL,6,FALSE())+IF(Q9=0,0,$EW9) -> 0 | ... BF9: =VLOOKUP(X9,MATERIAL,6,FALSE())+IF(X9=0,0,$EW9) -> 0 | BG9: =VLOOKUP(J9,MATERIAL,7,FALSE())+IF(J9=0,0,$EW9) -> 0 | BH9: =VLOOKUP(K9,MATERIAL,7,FALSE())+IF(K9=0,0,$EW9) -> 0 | BI9: =VLOOKUP(L9,MATERIAL,7,FALSE())+IF(L9=0,0,$EW9) -> 0 | BJ9: =VLOOKUP(M9,MATERIAL,7,FALSE())+IF(M9=0,0,$EW9) -> 0 | BK9: =VLOOKUP(N9,MATERIAL,7,FALSE())+IF(N9=0,0,$EW9) -> 0 | BL9: =VLOOKUP(O9,MATERIAL,7,FALSE())+IF(O9=0,0,$EW9) -> 0 | BM9: =VLOOKUP(P9,MATERIAL,7,FALSE())+IF(P9=0,0,$EW9) -> 0 | BN9: =VLOOKUP(Q9,MATERIAL,7,FALSE())+IF(Q9=0,0,$EW9) -> 0 | ... BU9: =VLOOKUP(X9,MATERIAL,7,FALSE())+IF(X9=0,0,$EW9) -> 0 | BV9: =VLOOKUP(J9,MATERIAL,8,FALSE())+IF(J9=0,0,$EW9) -> 0 | BW9: =VLOOKUP(K9,MATERIAL,8,FALSE())+IF(K9=0,0,$EW9) -> 0 | BX9: =VLOOKUP(L9,MATERIAL,8,FALSE())+IF(L9=0,0,$EW9) -> 0 | BY9: =VLOOKUP(M9,MATERIAL,8,FALSE())+IF(M9=0,0,$EW9) -> 0 | BZ9: =VLOOKUP(N9,MATERIAL,8,FALSE())+IF(N9=0,0,$EW9) -> 0 | CA9: =VLOOKUP(O9,MATERIAL,8,FALSE())+IF(O9=0,0,$EW9) -> 0 | CB9: =VLOOKUP(P9,MATERIAL,8,FALSE())+IF(P9=0,0,$EW9) -> 0 | CC9: =VLOOKUP(Q9,MATERIAL,8,FALSE())+IF(Q9=0,0,$EW9) -> 0 | ... CJ9: =VLOOKUP(X9,MATERIAL,8,FALSE())+IF(X9=0,0,$EW9) -> 0 | CK9: =VLOOKUP(J9,MATERIAL,4,FALSE()) -> 0 | CL9: =VLOOKUP(K9,MATERIAL,4,FALSE()) -> 0 | CM9: =VLOOKUP(L9,MATERIAL,4,FALSE()) -> 0 | CN9: =VLOOKUP(M9,MATERIAL,4,FALSE()) -> 0 | CO9: =VLOOKUP(N9,MATERIAL,4,FALSE()) -> 0 | CP9: =VLOOKUP(O9,MATERIAL,4,FALSE()) -> 0 | CQ9: =VLOOKUP(P9,MATERIAL,4,FALSE()) -> 0 | CR9: =VLOOKUP(Q9,MATERIAL,4,FALSE()) -> 0 | ... CY9: =VLOOKUP(X9,MATERIAL,4,FALSE()) -> 0 | CZ9: =IF(J9=0,0,LEFT(J9,1)) -> 0 | DA9: =IF(K9=0,0,LEFT(K9,1)) -> 0 | DB9: =IF(L9=0,0,LEFT(L9,1)) -> 0 | DC9: =IF(M9=0,0,LEFT(M9,1)) -> 0 | DD9: =IF(N9=0,0,LEFT(N9,1)) -> 0 | DE9: =IF(O9=0,0,LEFT(O9,1)) -> 0 | DF9: =IF(P9=0,0,LEFT(P9,1)) -> 0 | DG9: =IF(Q9=0,0,LEFT(Q9,1)) -> 0 | ... DN9: =IF(X9=0,0,LEFT(X9,1)) -> 0 | DO9: =SUMIF(CZ$5:CZ$32,$ED9,CK$5:CK$32) -> 1 | DP9: =SUMIF(DA$5:DA$32,$ED9,CL$5:CL$32) -> 0 | DQ9: =SUMIF(DB$5:DB$32,$ED9,CM$5:CM$32) -> 0 | DR9: =SUMIF(DC$5:DC$32,$ED9,CN$5:CN$32) -> 0 | DS9: =SUMIF(DD$5:DD$32,$ED9,CO$5:CO$32) -> 0 | DT9: =SUMIF(DE$5:DE$32,$ED9,CP$5:CP$32) -> 0 | DU9: =SUMIF(DF$5:DF$32,$ED9,CQ$5:CQ$32) -> 0 | DV9: =SUMIF(DG$5:DG$32,$ED9,CR$5:CR$32) -> 0 | ... EC9: =SUMIF(DN$5:DN$32,$ED9,CY$5:CY$32) -> 0 | ED9: K | EF9: =VLOOKUP(J9,MATERIAL,9,FALSE()) -> 0 | EG9: =VLOOKUP(K9,MATERIAL,9,FALSE()) -> 0 | EH9: =VLOOKUP(L9,MATERIAL,9,FALSE()) -> 0 | EI9: =VLOOKUP(M9,MATERIAL,9,FALSE()) -> 0 | EJ9: =VLOOKUP(N9,MATERIAL,9,FALSE()) -> 0 | EK9: =VLOOKUP(O9,MATERIAL,9,FALSE()) -> 0 | EL9: =VLOOKUP(P9,MATERIAL,9,FALSE()) -> 0 | EM9: =VLOOKUP(Q9,MATERIAL,9,FALSE()) -> 0 | ... ET9: =VLOOKUP(X9,MATERIAL,9,FALSE()) -> 0 | EU9: =IF($B9="",0,VLOOKUP($B9,ITEMS,EU$2,FALSE())) -> 0 | EV9: =VLOOKUP(EU9,MWS,2) -> 0 | EW9: =VLOOKUP(EU9,MWS,3) -> 0
A10: =EV10 -> 0 | B10: Buckram Leggings | C10: Fa | D10: =AD1 -> 0 | E10: =AS1 -> 0 | F10: =BH1 -> 0 | G10: =BW1 -> 0 | H10: =MAX(EG5:EG32) -> 0 | J10: =IF($B10="",0,VLOOKUP($B10,ITEMS,J$2,FALSE())) -> 0 | K10: =IF($B10="",0,VLOOKUP($B10,ITEMS,K$2,FALSE())) -> 0 | L10: =IF($B10="",0,VLOOKUP($B10,ITEMS,L$2,FALSE())) -> 0 | M10: =IF($B10="",0,VLOOKUP($B10,ITEMS,M$2,FALSE())) -> 0 | N10: =IF($B10="",0,VLOOKUP($B10,ITEMS,N$2,FALSE())) -> 0 | O10: =IF($B10="",0,VLOOKUP($B10,ITEMS,O$2,FALSE())) -> 0 | P10: =IF($B10="",0,VLOOKUP($B10,ITEMS,P$2,FALSE())) -> 0 | Q10: =IF($B10="",0,VLOOKUP($B10,ITEMS,Q$2,FALSE())) -> 0 | ... X10: =IF($B10="",0,VLOOKUP($B10,ITEMS,X$2,FALSE())) -> C | Y10: =IF($B10="",0,VLOOKUP($B10,ITEMS,17,FALSE())) -> 36 | Z10: =IF($B10="",0,VLOOKUP($B10,ITEMS,18,FALSE())) -> 1.8 | AA10: =IF($B10="",0,VLOOKUP($B10,ITEMS,19,FALSE())) -> 0 | AB10: =IF($B10="",0,VLOOKUP($B10,ITEMS,20,FALSE())) -> 0 | AC10: =VLOOKUP(J10,MATERIAL,5,FALSE())+IF(J10=0,0,$EW10) -> 0 | AD10: =VLOOKUP(K10,MATERIAL,5,FALSE())+IF(K10=0,0,$EW10) -> 0 | AE10: =VLOOKUP(L10,MATERIAL,5,FALSE())+IF(L10=0,0,$EW10) -> 0 | AF10: =VLOOKUP(M10,MATERIAL,5,FALSE())+IF(M10=0,0,$EW10) -> 0 | AG10: =VLOOKUP(N10,MATERIAL,5,FALSE())+IF(N10=0,0,$EW10) -> 0 | AH10: =VLOOKUP(O10,MATERIAL,5,FALSE())+IF(O10=0,0,$EW10) -> 0 | AI10: =VLOOKUP(P10,MATERIAL,5,FALSE())+IF(P10=0,0,$EW10) -> 0 | AJ10: =VLOOKUP(Q10,MATERIAL,5,FALSE())+IF(Q10=0,0,$EW10) -> 0 | ... AQ10: =VLOOKUP(X10,MATERIAL,5,FALSE())+IF(X10=0,0,$EW10) -> 0 | AR10: =VLOOKUP(J10,MATERIAL,6,FALSE())+IF(J10=0,0,$EW10) -> 0 | AS10: =VLOOKUP(K10,MATERIAL,6,FALSE())+IF(K10=0,0,$EW10) -> 0 | AT10: =VLOOKUP(L10,MATERIAL,6,FALSE())+IF(L10=0,0,$EW10) -> 0 | AU10: =VLOOKUP(M10,MATERIAL,6,FALSE())+IF(M10=0,0,$EW10) -> 0 | AV10: =VLOOKUP(N10,MATERIAL,6,FALSE())+IF(N10=0,0,$EW10) -> 0 | AW10: =VLOOKUP(O10,MATERIAL,6,FALSE())+IF(O10=0,0,$EW10) -> 0 | AX10: =VLOOKUP(P10,MATERIAL,6,FALSE())+IF(P10=0,0,$EW10) -> 0 | AY10: =VLOOKUP(Q10,MATERIAL,6,FALSE())+IF(Q10=0,0,$EW10) -> 0 | ... BF10: =VLOOKUP(X10,MATERIAL,6,FALSE())+IF(X10=0,0,$EW10) -> 1 | BG10: =VLOOKUP(J10,MATERIAL,7,FALSE())+IF(J10=0,0,$EW10) -> 0 | BH10: =VLOOKUP(K10,MATERIAL,7,FALSE())+IF(K10=0,0,$EW10) -> 0 | BI10: =VLOOKUP(L10,MATERIAL,7,FALSE())+IF(L10=0,0,$EW10) -> 0 | BJ10: =VLOOKUP(M10,MATERIAL,7,FALSE())+IF(M10=0,0,$EW10) -> 0 | BK10: =VLOOKUP(N10,MATERIAL,7,FALSE())+IF(N10=0,0,$EW10) -> 0 | BL10: =VLOOKUP(O10,MATERIAL,7,FALSE())+IF(O10=0,0,$EW10) -> 0 | BM10: =VLOOKUP(P10,MATERIAL,7,FALSE())+IF(P10=0,0,$EW10) -> 0 | BN10: =VLOOKUP(Q10,MATERIAL,7,FALSE())+IF(Q10=0,0,$EW10) -> 0 | ... BU10: =VLOOKUP(X10,MATERIAL,7,FALSE())+IF(X10=0,0,$EW10) -> 0 | BV10: =VLOOKUP(J10,MATERIAL,8,FALSE())+IF(J10=0,0,$EW10) -> 0 | BW10: =VLOOKUP(K10,MATERIAL,8,FALSE())+IF(K10=0,0,$EW10) -> 0 | BX10: =VLOOKUP(L10,MATERIAL,8,FALSE())+IF(L10=0,0,$EW10) -> 0 | BY10: =VLOOKUP(M10,MATERIAL,8,FALSE())+IF(M10=0,0,$EW10) -> 0 | BZ10: =VLOOKUP(N10,MATERIAL,8,FALSE())+IF(N10=0,0,$EW10) -> 0 | CA10: =VLOOKUP(O10,MATERIAL,8,FALSE())+IF(O10=0,0,$EW10) -> 0 | CB10: =VLOOKUP(P10,MATERIAL,8,FALSE())+IF(P10=0,0,$EW10) -> 0 | CC10: =VLOOKUP(Q10,MATERIAL,8,FALSE())+IF(Q10=0,0,$EW10) -> 0 | ... CJ10: =VLOOKUP(X10,MATERIAL,8,FALSE())+IF(X10=0,0,$EW10) -> 1 | CK10: =VLOOKUP(J10,MATERIAL,4,FALSE()) -> 0 | CL10: =VLOOKUP(K10,MATERIAL,4,FALSE()) -> 0 | CM10: =VLOOKUP(L10,MATERIAL,4,FALSE()) -> 0 | CN10: =VLOOKUP(M10,MATERIAL,4,FALSE()) -> 0 | CO10: =VLOOKUP(N10,MATERIAL,4,FALSE()) -> 0 | CP10: =VLOOKUP(O10,MATERIAL,4,FALSE()) -> 0 | CQ10: =VLOOKUP(P10,MATERIAL,4,FALSE()) -> 0 | CR10: =VLOOKUP(Q10,MATERIAL,4,FALSE()) -> 0 | ... CY10: =VLOOKUP(X10,MATERIAL,4,FALSE()) -> 1 | CZ10: =IF(J10=0,0,LEFT(J10,1)) -> 0 | DA10: =IF(K10=0,0,LEFT(K10,1)) -> 0 | DB10: =IF(L10=0,0,LEFT(L10,1)) -> 0 | DC10: =IF(M10=0,0,LEFT(M10,1)) -> 0 | DD10: =IF(N10=0,0,LEFT(N10,1)) -> 0 | DE10: =IF(O10=0,0,LEFT(O10,1)) -> 0 | DF10: =IF(P10=0,0,LEFT(P10,1)) -> 0 | DG10: =IF(Q10=0,0,LEFT(Q10,1)) -> 0 | ... DN10: =IF(X10=0,0,LEFT(X10,1)) -> C | DO10: =SUMIF(CZ$5:CZ$32,$ED10,CK$5:CK$32) -> 0 | DP10: =SUMIF(DA$5:DA$32,$ED10,CL$5:CL$32) -> 0 | DQ10: =SUMIF(DB$5:DB$32,$ED10,CM$5:CM$32) -> 0 | DR10: =SUMIF(DC$5:DC$32,$ED10,CN$5:CN$32) -> 0 | DS10: =SUMIF(DD$5:DD$32,$ED10,CO$5:CO$32) -> 0 | DT10: =SUMIF(DE$5:DE$32,$ED10,CP$5:CP$32) -> 0 | DU10: =SUMIF(DF$5:DF$32,$ED10,CQ$5:CQ$32) -> 0 | DV10: =SUMIF(DG$5:DG$32,$ED10,CR$5:CR$32) -> 0 | ... EC10: =SUMIF(DN$5:DN$32,$ED10,CY$5:CY$32) -> 0 | ED10: S | EF10: =VLOOKUP(J10,MATERIAL,9,FALSE()) -> 0 | EG10: =VLOOKUP(K10,MATERIAL,9,FALSE()) -> 0 | EH10: =VLOOKUP(L10,MATERIAL,9,FALSE()) -> 0 | EI10: =VLOOKUP(M10,MATERIAL,9,FALSE()) -> 0 | EJ10: =VLOOKUP(N10,MATERIAL,9,FALSE()) -> 0 | EK10: =VLOOKUP(O10,MATERIAL,9,FALSE()) -> 0 | EL10: =VLOOKUP(P10,MATERIAL,9,FALSE()) -> 0 | EM10: =VLOOKUP(Q10,MATERIAL,9,FALSE()) -> 0 | ... ET10: =VLOOKUP(X10,MATERIAL,9,FALSE()) -> 0 | EU10: =IF($B10="",0,VLOOKUP($B10,ITEMS,EU$2,FALSE())) -> 0 | EV10: =VLOOKUP(EU10,MWS,2) -> 0 | EW10: =VLOOKUP(EU10,MWS,3) -> 0
A11: =EV11 -> 0 | B11: Leather Shoes | C11: Nk | D11: =AE1 -> 0 | E11: =AT1 -> 0 | F11: =BI1 -> 0 | G11: =BX1 -> 0 | H11: =MAX(EH5:EH32) -> 0 | J11: =IF($B11="",0,VLOOKUP($B11,ITEMS,J$2,FALSE())) -> 0 | K11: =IF($B11="",0,VLOOKUP($B11,ITEMS,K$2,FALSE())) -> 0 | L11: =IF($B11="",0,VLOOKUP($B11,ITEMS,L$2,FALSE())) -> 0 | M11: =IF($B11="",0,VLOOKUP($B11,ITEMS,M$2,FALSE())) -> 0 | N11: =IF($B11="",0,VLOOKUP($B11,ITEMS,N$2,FALSE())) -> 0 | O11: =IF($B11="",0,VLOOKUP($B11,ITEMS,O$2,FALSE())) -> 0 | P11: =IF($B11="",0,VLOOKUP($B11,ITEMS,P$2,FALSE())) -> 0 | Q11: =IF($B11="",0,VLOOKUP($B11,ITEMS,Q$2,FALSE())) -> 0 | ... X11: =IF($B11="",0,VLOOKUP($B11,ITEMS,X$2,FALSE())) -> L | Y11: =IF($B11="",0,VLOOKUP($B11,ITEMS,17,FALSE())) -> 28 | Z11: =IF($B11="",0,VLOOKUP($B11,ITEMS,18,FALSE())) -> 1.05 | AA11: =IF($B11="",0,VLOOKUP($B11,ITEMS,19,FALSE())) -> 0 | AB11: =IF($B11="",0,VLOOKUP($B11,ITEMS,20,FALSE())) -> 0 | AC11: =VLOOKUP(J11,MATERIAL,5,FALSE())+IF(J11=0,0,$EW11) -> 0 | AD11: =VLOOKUP(K11,MATERIAL,5,FALSE())+IF(K11=0,0,$EW11) -> 0 | AE11: =VLOOKUP(L11,MATERIAL,5,FALSE())+IF(L11=0,0,$EW11) -> 0 | AF11: =VLOOKUP(M11,MATERIAL,5,FALSE())+IF(M11=0,0,$EW11) -> 0 | AG11: =VLOOKUP(N11,MATERIAL,5,FALSE())+IF(N11=0,0,$EW11) -> 0 | AH11: =VLOOKUP(O11,MATERIAL,5,FALSE())+IF(O11=0,0,$EW11) -> 0 | AI11: =VLOOKUP(P11,MATERIAL,5,FALSE())+IF(P11=0,0,$EW11) -> 0 | AJ11: =VLOOKUP(Q11,MATERIAL,5,FALSE())+IF(Q11=0,0,$EW11) -> 0 | ... AQ11: =VLOOKUP(X11,MATERIAL,5,FALSE())+IF(X11=0,0,$EW11) -> 1 | AR11: =VLOOKUP(J11,MATERIAL,6,FALSE())+IF(J11=0,0,$EW11) -> 0 | AS11: =VLOOKUP(K11,MATERIAL,6,FALSE())+IF(K11=0,0,$EW11) -> 0 | AT11: =VLOOKUP(L11,MATERIAL,6,FALSE())+IF(L11=0,0,$EW11) -> 0 | AU11: =VLOOKUP(M11,MATERIAL,6,FALSE())+IF(M11=0,0,$EW11) -> 0 | AV11: =VLOOKUP(N11,MATERIAL,6,FALSE())+IF(N11=0,0,$EW11) -> 0 | AW11: =VLOOKUP(O11,MATERIAL,6,FALSE())+IF(O11=0,0,$EW11) -> 0 | AX11: =VLOOKUP(P11,MATERIAL,6,FALSE())+IF(P11=0,0,$EW11) -> 0 | AY11: =VLOOKUP(Q11,MATERIAL,6,FALSE())+IF(Q11=0,0,$EW11) -> 0 | ... BF11: =VLOOKUP(X11,MATERIAL,6,FALSE())+IF(X11=0,0,$EW11) -> 2 | BG11: =VLOOKUP(J11,MATERIAL,7,FALSE())+IF(J11=0,0,$EW11) -> 0 | BH11: =VLOOKUP(K11,MATERIAL,7,FALSE())+IF(K11=0,0,$EW11) -> 0 | BI11: =VLOOKUP(L11,MATERIAL,7,FALSE())+IF(L11=0,0,$EW11) -> 0 | BJ11: =VLOOKUP(M11,MATERIAL,7,FALSE())+IF(M11=0,0,$EW11) -> 0 | BK11: =VLOOKUP(N11,MATERIAL,7,FALSE())+IF(N11=0,0,$EW11) -> 0 | BL11: =VLOOKUP(O11,MATERIAL,7,FALSE())+IF(O11=0,0,$EW11) -> 0 | BM11: =VLOOKUP(P11,MATERIAL,7,FALSE())+IF(P11=0,0,$EW11) -> 0 | BN11: =VLOOKUP(Q11,MATERIAL,7,FALSE())+IF(Q11=0,0,$EW11) -> 0 | ... BU11: =VLOOKUP(X11,MATERIAL,7,FALSE())+IF(X11=0,0,$EW11) -> 1 | BV11: =VLOOKUP(J11,MATERIAL,8,FALSE())+IF(J11=0,0,$EW11) -> 0 | BW11: =VLOOKUP(K11,MATERIAL,8,FALSE())+IF(K11=0,0,$EW11) -> 0 | BX11: =VLOOKUP(L11,MATERIAL,8,FALSE())+IF(L11=0,0,$EW11) -> 0 | BY11: =VLOOKUP(M11,MATERIAL,8,FALSE())+IF(M11=0,0,$EW11) -> 0 | BZ11: =VLOOKUP(N11,MATERIAL,8,FALSE())+IF(N11=0,0,$EW11) -> 0 | CA11: =VLOOKUP(O11,MATERIAL,8,FALSE())+IF(O11=0,0,$EW11) -> 0 | CB11: =VLOOKUP(P11,MATERIAL,8,FALSE())+IF(P11=0,0,$EW11) -> 0 | CC11: =VLOOKUP(Q11,MATERIAL,8,FALSE())+IF(Q11=0,0,$EW11) -> 0 | ... CJ11: =VLOOKUP(X11,MATERIAL,8,FALSE())+IF(X11=0,0,$EW11) -> 3 | CK11: =VLOOKUP(J11,MATERIAL,4,FALSE()) -> 0 | CL11: =VLOOKUP(K11,MATERIAL,4,FALSE()) -> 0 | CM11: =VLOOKUP(L11,MATERIAL,4,FALSE()) -> 0 | CN11: =VLOOKUP(M11,MATERIAL,4,FALSE()) -> 0 | CO11: =VLOOKUP(N11,MATERIAL,4,FALSE()) -> 0 | CP11: =VLOOKUP(O11,MATERIAL,4,FALSE()) -> 0 | CQ11: =VLOOKUP(P11,MATERIAL,4,FALSE()) -> 0 | CR11: =VLOOKUP(Q11,MATERIAL,4,FALSE()) -> 0 | ... CY11: =VLOOKUP(X11,MATERIAL,4,FALSE()) -> 1 | CZ11: =IF(J11=0,0,LEFT(J11,1)) -> 0 | DA11: =IF(K11=0,0,LEFT(K11,1)) -> 0 | DB11: =IF(L11=0,0,LEFT(L11,1)) -> 0 | DC11: =IF(M11=0,0,LEFT(M11,1)) -> 0 | DD11: =IF(N11=0,0,LEFT(N11,1)) -> 0 | DE11: =IF(O11=0,0,LEFT(O11,1)) -> 0 | DF11: =IF(P11=0,0,LEFT(P11,1)) -> 0 | DG11: =IF(Q11=0,0,LEFT(Q11,1)) -> 0 | ... DN11: =IF(X11=0,0,LEFT(X11,1)) -> L | DO11: =SUMIF(CZ$5:CZ$32,$ED11,CK$5:CK$32) -> 0 | DP11: =SUMIF(DA$5:DA$32,$ED11,CL$5:CL$32) -> 0 | DQ11: =SUMIF(DB$5:DB$32,$ED11,CM$5:CM$32) -> 0 | DR11: =SUMIF(DC$5:DC$32,$ED11,CN$5:CN$32) -> 0 | DS11: =SUMIF(DD$5:DD$32,$ED11,CO$5:CO$32) -> 0 | DT11: =SUMIF(DE$5:DE$32,$ED11,CP$5:CP$32) -> 0 | DU11: =SUMIF(DF$5:DF$32,$ED11,CQ$5:CQ$32) -> 0 | DV11: =SUMIF(DG$5:DG$32,$ED11,CR$5:CR$32) -> 0 | ... EC11: =SUMIF(DN$5:DN$32,$ED11,CY$5:CY$32) -> 0 | ED11: M | EF11: =VLOOKUP(J11,MATERIAL,9,FALSE()) -> 0 | EG11: =VLOOKUP(K11,MATERIAL,9,FALSE()) -> 0 | EH11: =VLOOKUP(L11,MATERIAL,9,FALSE()) -> 0 | EI11: =VLOOKUP(M11,MATERIAL,9,FALSE()) -> 0 | EJ11: =VLOOKUP(N11,MATERIAL,9,FALSE()) -> 0 | EK11: =VLOOKUP(O11,MATERIAL,9,FALSE()) -> 0 | EL11: =VLOOKUP(P11,MATERIAL,9,FALSE()) -> 0 | EM11: =VLOOKUP(Q11,MATERIAL,9,FALSE()) -> 0 | ... ET11: =VLOOKUP(X11,MATERIAL,9,FALSE()) -> 0 | EU11: =IF($B11="",0,VLOOKUP($B11,ITEMS,EU$2,FALSE())) -> 0 | EV11: =VLOOKUP(EU11,MWS,2) -> 0 | EW11: =VLOOKUP(EU11,MWS,3) -> 0
A12: =EV12 -> 0 | B12: Buckram Cloak | C12: Sh | D12: =AF1 -> 4 | E12: =AU1 -> 4 | F12: =BJ1 -> 2 | G12: =BY1 -> 5 | H12: =MAX(EI5:EI32) -> 0 | J12: =IF($B12="",0,VLOOKUP($B12,ITEMS,J$2,FALSE())) -> 0 | K12: =IF($B12="",0,VLOOKUP($B12,ITEMS,K$2,FALSE())) -> 0 | L12: =IF($B12="",0,VLOOKUP($B12,ITEMS,L$2,FALSE())) -> 0 | M12: =IF($B12="",0,VLOOKUP($B12,ITEMS,M$2,FALSE())) -> Cb | N12: =IF($B12="",0,VLOOKUP($B12,ITEMS,N$2,FALSE())) -> 0 | O12: =IF($B12="",0,VLOOKUP($B12,ITEMS,O$2,FALSE())) -> 0 | P12: =IF($B12="",0,VLOOKUP($B12,ITEMS,P$2,FALSE())) -> 0 | Q12: =IF($B12="",0,VLOOKUP($B12,ITEMS,Q$2,FALSE())) -> 0 | ... X12: =IF($B12="",0,VLOOKUP($B12,ITEMS,X$2,FALSE())) -> 0 | Y12: =IF($B12="",0,VLOOKUP($B12,ITEMS,17,FALSE())) -> 66 | Z12: =IF($B12="",0,VLOOKUP($B12,ITEMS,18,FALSE())) -> 3.3 | AA12: =IF($B12="",0,VLOOKUP($B12,ITEMS,19,FALSE())) -> 0 | AB12: =IF($B12="",0,VLOOKUP($B12,ITEMS,20,FALSE())) -> 0 | AC12: =VLOOKUP(J12,MATERIAL,5,FALSE())+IF(J12=0,0,$EW12) -> 0 | AD12: =VLOOKUP(K12,MATERIAL,5,FALSE())+IF(K12=0,0,$EW12) -> 0 | AE12: =VLOOKUP(L12,MATERIAL,5,FALSE())+IF(L12=0,0,$EW12) -> 0 | AF12: =VLOOKUP(M12,MATERIAL,5,FALSE())+IF(M12=0,0,$EW12) -> 0 | AG12: =VLOOKUP(N12,MATERIAL,5,FALSE())+IF(N12=0,0,$EW12) -> 0 | AH12: =VLOOKUP(O12,MATERIAL,5,FALSE())+IF(O12=0,0,$EW12) -> 0 | AI12: =VLOOKUP(P12,MATERIAL,5,FALSE())+IF(P12=0,0,$EW12) -> 0 | AJ12: =VLOOKUP(Q12,MATERIAL,5,FALSE())+IF(Q12=0,0,$EW12) -> 0 | ... AQ12: =VLOOKUP(X12,MATERIAL,5,FALSE())+IF(X12=0,0,$EW12) -> 0 | AR12: =VLOOKUP(J12,MATERIAL,6,FALSE())+IF(J12=0,0,$EW12) -> 0 | AS12: =VLOOKUP(K12,MATERIAL,6,FALSE())+IF(K12=0,0,$EW12) -> 0 | AT12: =VLOOKUP(L12,MATERIAL,6,FALSE())+IF(L12=0,0,$EW12) -> 0 | AU12: =VLOOKUP(M12,MATERIAL,6,FALSE())+IF(M12=0,0,$EW12) -> 0 | AV12: =VLOOKUP(N12,MATERIAL,6,FALSE())+IF(N12=0,0,$EW12) -> 0 | AW12: =VLOOKUP(O12,MATERIAL,6,FALSE())+IF(O12=0,0,$EW12) -> 0 | AX12: =VLOOKUP(P12,MATERIAL,6,FALSE())+IF(P12=0,0,$EW12) -> 0 | AY12: =VLOOKUP(Q12,MATERIAL,6,FALSE())+IF(Q12=0,0,$EW12) -> 0 | ... BF12: =VLOOKUP(X12,MATERIAL,6,FALSE())+IF(X12=0,0,$EW12) -> 0 | BG12: =VLOOKUP(J12,MATERIAL,7,FALSE())+IF(J12=0,0,$EW12) -> 0 | BH12: =VLOOKUP(K12,MATERIAL,7,FALSE())+IF(K12=0,0,$EW12) -> 0 | BI12: =VLOOKUP(L12,MATERIAL,7,FALSE())+IF(L12=0,0,$EW12) -> 0 | BJ12: =VLOOKUP(M12,MATERIAL,7,FALSE())+IF(M12=0,0,$EW12) -> 0 | BK12: =VLOOKUP(N12,MATERIAL,7,FALSE())+IF(N12=0,0,$EW12) -> 0 | BL12: =VLOOKUP(O12,MATERIAL,7,FALSE())+IF(O12=0,0,$EW12) -> 0 | BM12: =VLOOKUP(P12,MATERIAL,7,FALSE())+IF(P12=0,0,$EW12) -> 0 | BN12: =VLOOKUP(Q12,MATERIAL,7,FALSE())+IF(Q12=0,0,$EW12) -> 0 | ... BU12: =VLOOKUP(X12,MATERIAL,7,FALSE())+IF(X12=0,0,$EW12) -> 0 | BV12: =VLOOKUP(J12,MATERIAL,8,FALSE())+IF(J12=0,0,$EW12) -> 0 | BW12: =VLOOKUP(K12,MATERIAL,8,FALSE())+IF(K12=0,0,$EW12) -> 0 | BX12: =VLOOKUP(L12,MATERIAL,8,FALSE())+IF(L12=0,0,$EW12) -> 0 | BY12: =VLOOKUP(M12,MATERIAL,8,FALSE())+IF(M12=0,0,$EW12) -> 1 | BZ12: =VLOOKUP(N12,MATERIAL,8,FALSE())+IF(N12=0,0,$EW12) -> 0 | CA12: =VLOOKUP(O12,MATERIAL,8,FALSE())+IF(O12=0,0,$EW12) -> 0 | CB12: =VLOOKUP(P12,MATERIAL,8,FALSE())+IF(P12=0,0,$EW12) -> 0 | CC12: =VLOOKUP(Q12,MATERIAL,8,FALSE())+IF(Q12=0,0,$EW12) -> 0 | ... CJ12: =VLOOKUP(X12,MATERIAL,8,FALSE())+IF(X12=0,0,$EW12) -> 0 | CK12: =VLOOKUP(J12,MATERIAL,4,FALSE()) -> 0 | CL12: =VLOOKUP(K12,MATERIAL,4,FALSE()) -> 0 | CM12: =VLOOKUP(L12,MATERIAL,4,FALSE()) -> 0 | CN12: =VLOOKUP(M12,MATERIAL,4,FALSE()) -> 0.5 | CO12: =VLOOKUP(N12,MATERIAL,4,FALSE()) -> 0 | CP12: =VLOOKUP(O12,MATERIAL,4,FALSE()) -> 0 | CQ12: =VLOOKUP(P12,MATERIAL,4,FALSE()) -> 0 | CR12: =VLOOKUP(Q12,MATERIAL,4,FALSE()) -> 0 | ... CY12: =VLOOKUP(X12,MATERIAL,4,FALSE()) -> 0 | CZ12: =IF(J12=0,0,LEFT(J12,1)) -> 0 | DA12: =IF(K12=0,0,LEFT(K12,1)) -> 0 | DB12: =IF(L12=0,0,LEFT(L12,1)) -> 0 | DC12: =IF(M12=0,0,LEFT(M12,1)) -> C | DD12: =IF(N12=0,0,LEFT(N12,1)) -> 0 | DE12: =IF(O12=0,0,LEFT(O12,1)) -> 0 | DF12: =IF(P12=0,0,LEFT(P12,1)) -> 0 | DG12: =IF(Q12=0,0,LEFT(Q12,1)) -> 0 | ... DN12: =IF(X12=0,0,LEFT(X12,1)) -> 0 | DO12: =SUMIF(CZ$5:CZ$32,$ED12,CK$5:CK$32) -> 0 | DP12: =SUMIF(DA$5:DA$32,$ED12,CL$5:CL$32) -> 0 | DQ12: =SUMIF(DB$5:DB$32,$ED12,CM$5:CM$32) -> 0 | DR12: =SUMIF(DC$5:DC$32,$ED12,CN$5:CN$32) -> 0 | DS12: =SUMIF(DD$5:DD$32,$ED12,CO$5:CO$32) -> 0 | DT12: =SUMIF(DE$5:DE$32,$ED12,CP$5:CP$32) -> 0 | DU12: =SUMIF(DF$5:DF$32,$ED12,CQ$5:CQ$32) -> 0 | DV12: =SUMIF(DG$5:DG$32,$ED12,CR$5:CR$32) -> 0 | ... EC12: =SUMIF(DN$5:DN$32,$ED12,CY$5:CY$32) -> 0 | ED12: P | EF12: =VLOOKUP(J12,MATERIAL,9,FALSE()) -> 0 | EG12: =VLOOKUP(K12,MATERIAL,9,FALSE()) -> 0 | EH12: =VLOOKUP(L12,MATERIAL,9,FALSE()) -> 0 | EI12: =VLOOKUP(M12,MATERIAL,9,FALSE()) -> 0 | EJ12: =VLOOKUP(N12,MATERIAL,9,FALSE()) -> 0 | EK12: =VLOOKUP(O12,MATERIAL,9,FALSE()) -> 0 | EL12: =VLOOKUP(P12,MATERIAL,9,FALSE()) -> 0 | EM12: =VLOOKUP(Q12,MATERIAL,9,FALSE()) -> 0 | ... ET12: =VLOOKUP(X12,MATERIAL,9,FALSE()) -> 0 | EU12: =IF($B12="",0,VLOOKUP($B12,ITEMS,EU$2,FALSE())) -> 0 | EV12: =VLOOKUP(EU12,MWS,2) -> 0 | EW12: =VLOOKUP(EU12,MWS,3) -> 0
A13: =EV13 -> 0 | C13: Ua | D13: =AG1 -> 4 | E13: =AV1 -> 4 | F13: =BK1 -> 2 | G13: =BZ1 -> 4 | H13: =MAX(EJ5:EJ32) -> 0 | J13: =IF($B13="",0,VLOOKUP($B13,ITEMS,J$2,FALSE())) -> 0 | K13: =IF($B13="",0,VLOOKUP($B13,ITEMS,K$2,FALSE())) -> 0 | L13: =IF($B13="",0,VLOOKUP($B13,ITEMS,L$2,FALSE())) -> 0 | M13: =IF($B13="",0,VLOOKUP($B13,ITEMS,M$2,FALSE())) -> 0 | N13: =IF($B13="",0,VLOOKUP($B13,ITEMS,N$2,FALSE())) -> 0 | O13: =IF($B13="",0,VLOOKUP($B13,ITEMS,O$2,FALSE())) -> 0 | P13: =IF($B13="",0,VLOOKUP($B13,ITEMS,P$2,FALSE())) -> 0 | Q13: =IF($B13="",0,VLOOKUP($B13,ITEMS,Q$2,FALSE())) -> 0 | ... X13: =IF($B13="",0,VLOOKUP($B13,ITEMS,X$2,FALSE())) -> 0 | Y13: =IF($B13="",0,VLOOKUP($B13,ITEMS,17,FALSE())) -> 0 | Z13: =IF($B13="",0,VLOOKUP($B13,ITEMS,18,FALSE())) -> 0 | AA13: =IF($B13="",0,VLOOKUP($B13,ITEMS,19,FALSE())) -> 0 | AB13: =IF($B13="",0,VLOOKUP($B13,ITEMS,20,FALSE())) -> 0 | AC13: =VLOOKUP(J13,MATERIAL,5,FALSE())+IF(J13=0,0,$EW13) -> 0 | AD13: =VLOOKUP(K13,MATERIAL,5,FALSE())+IF(K13=0,0,$EW13) -> 0 | AE13: =VLOOKUP(L13,MATERIAL,5,FALSE())+IF(L13=0,0,$EW13) -> 0 | AF13: =VLOOKUP(M13,MATERIAL,5,FALSE())+IF(M13=0,0,$EW13) -> 0 | AG13: =VLOOKUP(N13,MATERIAL,5,FALSE())+IF(N13=0,0,$EW13) -> 0 | AH13: =VLOOKUP(O13,MATERIAL,5,FALSE())+IF(O13=0,0,$EW13) -> 0 | AI13: =VLOOKUP(P13,MATERIAL,5,FALSE())+IF(P13=0,0,$EW13) -> 0 | AJ13: =VLOOKUP(Q13,MATERIAL,5,FALSE())+IF(Q13=0,0,$EW13) -> 0 | ... AQ13: =VLOOKUP(X13,MATERIAL,5,FALSE())+IF(X13=0,0,$EW13) -> 0 | AR13: =VLOOKUP(J13,MATERIAL,6,FALSE())+IF(J13=0,0,$EW13) -> 0 | AS13: =VLOOKUP(K13,MATERIAL,6,FALSE())+IF(K13=0,0,$EW13) -> 0 | AT13: =VLOOKUP(L13,MATERIAL,6,FALSE())+IF(L13=0,0,$EW13) -> 0 | AU13: =VLOOKUP(M13,MATERIAL,6,FALSE())+IF(M13=0,0,$EW13) -> 0 | AV13: =VLOOKUP(N13,MATERIAL,6,FALSE())+IF(N13=0,0,$EW13) -> 0 | AW13: =VLOOKUP(O13,MATERIAL,6,FALSE())+IF(O13=0,0,$EW13) -> 0 | AX13: =VLOOKUP(P13,MATERIAL,6,FALSE())+IF(P13=0,0,$EW13) -> 0 | AY13: =VLOOKUP(Q13,MATERIAL,6,FALSE())+IF(Q13=0,0,$EW13) -> 0 | ... BF13: =VLOOKUP(X13,MATERIAL,6,FALSE())+IF(X13=0,0,$EW13) -> 0 | BG13: =VLOOKUP(J13,MATERIAL,7,FALSE())+IF(J13=0,0,$EW13) -> 0 | BH13: =VLOOKUP(K13,MATERIAL,7,FALSE())+IF(K13=0,0,$EW13) -> 0 | BI13: =VLOOKUP(L13,MATERIAL,7,FALSE())+IF(L13=0,0,$EW13) -> 0 | BJ13: =VLOOKUP(M13,MATERIAL,7,FALSE())+IF(M13=0,0,$EW13) -> 0 | BK13: =VLOOKUP(N13,MATERIAL,7,FALSE())+IF(N13=0,0,$EW13) -> 0 | BL13: =VLOOKUP(O13,MATERIAL,7,FALSE())+IF(O13=0,0,$EW13) -> 0 | BM13: =VLOOKUP(P13,MATERIAL,7,FALSE())+IF(P13=0,0,$EW13) -> 0 | BN13: =VLOOKUP(Q13,MATERIAL,7,FALSE())+IF(Q13=0,0,$EW13) -> 0 | ... BU13: =VLOOKUP(X13,MATERIAL,7,FALSE())+IF(X13=0,0,$EW13) -> 0 | BV13: =VLOOKUP(J13,MATERIAL,8,FALSE())+IF(J13=0,0,$EW13) -> 0 | BW13: =VLOOKUP(K13,MATERIAL,8,FALSE())+IF(K13=0,0,$EW13) -> 0 | BX13: =VLOOKUP(L13,MATERIAL,8,FALSE())+IF(L13=0,0,$EW13) -> 0 | BY13: =VLOOKUP(M13,MATERIAL,8,FALSE())+IF(M13=0,0,$EW13) -> 0 | BZ13: =VLOOKUP(N13,MATERIAL,8,FALSE())+IF(N13=0,0,$EW13) -> 0 | CA13: =VLOOKUP(O13,MATERIAL,8,FALSE())+IF(O13=0,0,$EW13) -> 0 | CB13: =VLOOKUP(P13,MATERIAL,8,FALSE())+IF(P13=0,0,$EW13) -> 0 | CC13: =VLOOKUP(Q13,MATERIAL,8,FALSE())+IF(Q13=0,0,$EW13) -> 0 | ... CJ13: =VLOOKUP(X13,MATERIAL,8,FALSE())+IF(X13=0,0,$EW13) -> 0 | CK13: =VLOOKUP(J13,MATERIAL,4,FALSE()) -> 0 | CL13: =VLOOKUP(K13,MATERIAL,4,FALSE()) -> 0 | CM13: =VLOOKUP(L13,MATERIAL,4,FALSE()) -> 0 | CN13: =VLOOKUP(M13,MATERIAL,4,FALSE()) -> 0 | CO13: =VLOOKUP(N13,MATERIAL,4,FALSE()) -> 0 | CP13: =VLOOKUP(O13,MATERIAL,4,FALSE()) -> 0 | CQ13: =VLOOKUP(P13,MATERIAL,4,FALSE()) -> 0 | CR13: =VLOOKUP(Q13,MATERIAL,4,FALSE()) -> 0 | ... CY13: =VLOOKUP(X13,MATERIAL,4,FALSE()) -> 0 | CZ13: =IF(J13=0,0,LEFT(J13,1)) -> 0 | DA13: =IF(K13=0,0,LEFT(K13,1)) -> 0 | DB13: =IF(L13=0,0,LEFT(L13,1)) -> 0 | DC13: =IF(M13=0,0,LEFT(M13,1)) -> 0 | DD13: =IF(N13=0,0,LEFT(N13,1)) -> 0 | DE13: =IF(O13=0,0,LEFT(O13,1)) -> 0 | DF13: =IF(P13=0,0,LEFT(P13,1)) -> 0 | DG13: =IF(Q13=0,0,LEFT(Q13,1)) -> 0 | ... DN13: =IF(X13=0,0,LEFT(X13,1)) -> 0 | EF13: =VLOOKUP(J13,MATERIAL,9,FALSE()) -> 0 | EG13: =VLOOKUP(K13,MATERIAL,9,FALSE()) -> 0 | EH13: =VLOOKUP(L13,MATERIAL,9,FALSE()) -> 0 | EI13: =VLOOKUP(M13,MATERIAL,9,FALSE()) -> 0 | EJ13: =VLOOKUP(N13,MATERIAL,9,FALSE()) -> 0 | EK13: =VLOOKUP(O13,MATERIAL,9,FALSE()) -> 0 | EL13: =VLOOKUP(P13,MATERIAL,9,FALSE()) -> 0 | EM13: =VLOOKUP(Q13,MATERIAL,9,FALSE()) -> 0 | ... ET13: =VLOOKUP(X13,MATERIAL,9,FALSE()) -> 0 | EU13: =IF($B13="",0,VLOOKUP($B13,ITEMS,EU$2,FALSE())) -> 0 | EV13: =VLOOKUP(EU13,MWS,2) -> 0 | EW13: =VLOOKUP(EU13,MWS,3) -> 0
A14: =EV14 -> 0 | C14: El | D14: =AH1 -> 4 | E14: =AW1 -> 4 | F14: =BL1 -> 2 | G14: =CA1 -> 4 | H14: =MAX(EK5:EK32) -> 0 | J14: =IF($B14="",0,VLOOKUP($B14,ITEMS,J$2,FALSE())) -> 0 | K14: =IF($B14="",0,VLOOKUP($B14,ITEMS,K$2,FALSE())) -> 0 | L14: =IF($B14="",0,VLOOKUP($B14,ITEMS,L$2,FALSE())) -> 0 | M14: =IF($B14="",0,VLOOKUP($B14,ITEMS,M$2,FALSE())) -> 0 | N14: =IF($B14="",0,VLOOKUP($B14,ITEMS,N$2,FALSE())) -> 0 | O14: =IF($B14="",0,VLOOKUP($B14,ITEMS,O$2,FALSE())) -> 0 | P14: =IF($B14="",0,VLOOKUP($B14,ITEMS,P$2,FALSE())) -> 0 | Q14: =IF($B14="",0,VLOOKUP($B14,ITEMS,Q$2,FALSE())) -> 0 | ... X14: =IF($B14="",0,VLOOKUP($B14,ITEMS,X$2,FALSE())) -> 0 | Y14: =IF($B14="",0,VLOOKUP($B14,ITEMS,17,FALSE())) -> 0 | Z14: =IF($B14="",0,VLOOKUP($B14,ITEMS,18,FALSE())) -> 0 | AA14: =IF($B14="",0,VLOOKUP($B14,ITEMS,19,FALSE())) -> 0 | AB14: =IF($B14="",0,VLOOKUP($B14,ITEMS,20,FALSE())) -> 0 | AC14: =VLOOKUP(J14,MATERIAL,5,FALSE())+IF(J14=0,0,$EW14) -> 0 | AD14: =VLOOKUP(K14,MATERIAL,5,FALSE())+IF(K14=0,0,$EW14) -> 0 | AE14: =VLOOKUP(L14,MATERIAL,5,FALSE())+IF(L14=0,0,$EW14) -> 0 | AF14: =VLOOKUP(M14,MATERIAL,5,FALSE())+IF(M14=0,0,$EW14) -> 0 | AG14: =VLOOKUP(N14,MATERIAL,5,FALSE())+IF(N14=0,0,$EW14) -> 0 | AH14: =VLOOKUP(O14,MATERIAL,5,FALSE())+IF(O14=0,0,$EW14) -> 0 | AI14: =VLOOKUP(P14,MATERIAL,5,FALSE())+IF(P14=0,0,$EW14) -> 0 | AJ14: =VLOOKUP(Q14,MATERIAL,5,FALSE())+IF(Q14=0,0,$EW14) -> 0 | ... AQ14: =VLOOKUP(X14,MATERIAL,5,FALSE())+IF(X14=0,0,$EW14) -> 0 | AR14: =VLOOKUP(J14,MATERIAL,6,FALSE())+IF(J14=0,0,$EW14) -> 0 | AS14: =VLOOKUP(K14,MATERIAL,6,FALSE())+IF(K14=0,0,$EW14) -> 0 | AT14: =VLOOKUP(L14,MATERIAL,6,FALSE())+IF(L14=0,0,$EW14) -> 0 | AU14: =VLOOKUP(M14,MATERIAL,6,FALSE())+IF(M14=0,0,$EW14) -> 0 | AV14: =VLOOKUP(N14,MATERIAL,6,FALSE())+IF(N14=0,0,$EW14) -> 0 | AW14: =VLOOKUP(O14,MATERIAL,6,FALSE())+IF(O14=0,0,$EW14) -> 0 | AX14: =VLOOKUP(P14,MATERIAL,6,FALSE())+IF(P14=0,0,$EW14) -> 0 | AY14: =VLOOKUP(Q14,MATERIAL,6,FALSE())+IF(Q14=0,0,$EW14) -> 0 | ... BF14: =VLOOKUP(X14,MATERIAL,6,FALSE())+IF(X14=0,0,$EW14) -> 0 | BG14: =VLOOKUP(J14,MATERIAL,7,FALSE())+IF(J14=0,0,$EW14) -> 0 | BH14: =VLOOKUP(K14,MATERIAL,7,FALSE())+IF(K14=0,0,$EW14) -> 0 | BI14: =VLOOKUP(L14,MATERIAL,7,FALSE())+IF(L14=0,0,$EW14) -> 0 | BJ14: =VLOOKUP(M14,MATERIAL,7,FALSE())+IF(M14=0,0,$EW14) -> 0 | BK14: =VLOOKUP(N14,MATERIAL,7,FALSE())+IF(N14=0,0,$EW14) -> 0 | BL14: =VLOOKUP(O14,MATERIAL,7,FALSE())+IF(O14=0,0,$EW14) -> 0 | BM14: =VLOOKUP(P14,MATERIAL,7,FALSE())+IF(P14=0,0,$EW14) -> 0 | BN14: =VLOOKUP(Q14,MATERIAL,7,FALSE())+IF(Q14=0,0,$EW14) -> 0 | ... BU14: =VLOOKUP(X14,MATERIAL,7,FALSE())+IF(X14=0,0,$EW14) -> 0 | BV14: =VLOOKUP(J14,MATERIAL,8,FALSE())+IF(J14=0,0,$EW14) -> 0 | BW14: =VLOOKUP(K14,MATERIAL,8,FALSE())+IF(K14=0,0,$EW14) -> 0 | BX14: =VLOOKUP(L14,MATERIAL,8,FALSE())+IF(L14=0,0,$EW14) -> 0 | BY14: =VLOOKUP(M14,MATERIAL,8,FALSE())+IF(M14=0,0,$EW14) -> 0 | BZ14: =VLOOKUP(N14,MATERIAL,8,FALSE())+IF(N14=0,0,$EW14) -> 0 | CA14: =VLOOKUP(O14,MATERIAL,8,FALSE())+IF(O14=0,0,$EW14) -> 0 | CB14: =VLOOKUP(P14,MATERIAL,8,FALSE())+IF(P14=0,0,$EW14) -> 0 | CC14: =VLOOKUP(Q14,MATERIAL,8,FALSE())+IF(Q14=0,0,$EW14) -> 0 | ... CJ14: =VLOOKUP(X14,MATERIAL,8,FALSE())+IF(X14=0,0,$EW14) -> 0 | CK14: =VLOOKUP(J14,MATERIAL,4,FALSE()) -> 0 | CL14: =VLOOKUP(K14,MATERIAL,4,FALSE()) -> 0 | CM14: =VLOOKUP(L14,MATERIAL,4,FALSE()) -> 0 | CN14: =VLOOKUP(M14,MATERIAL,4,FALSE()) -> 0 | CO14: =VLOOKUP(N14,MATERIAL,4,FALSE()) -> 0 | CP14: =VLOOKUP(O14,MATERIAL,4,FALSE()) -> 0 | CQ14: =VLOOKUP(P14,MATERIAL,4,FALSE()) -> 0 | CR14: =VLOOKUP(Q14,MATERIAL,4,FALSE()) -> 0 | ... CY14: =VLOOKUP(X14,MATERIAL,4,FALSE()) -> 0 | CZ14: =IF(J14=0,0,LEFT(J14,1)) -> 0 | DA14: =IF(K14=0,0,LEFT(K14,1)) -> 0 | DB14: =IF(L14=0,0,LEFT(L14,1)) -> 0 | DC14: =IF(M14=0,0,LEFT(M14,1)) -> 0 | DD14: =IF(N14=0,0,LEFT(N14,1)) -> 0 | DE14: =IF(O14=0,0,LEFT(O14,1)) -> 0 | DF14: =IF(P14=0,0,LEFT(P14,1)) -> 0 | DG14: =IF(Q14=0,0,LEFT(Q14,1)) -> 0 | ... DN14: =IF(X14=0,0,LEFT(X14,1)) -> 0 | DO14: =SUM(CK5:CK32) -> 2.5 | DP14: =SUM(CL5:CL32) -> 0 | DQ14: =SUM(CM5:CM32) -> 0 | DR14: =SUM(CN5:CN32) -> 3.5 | DS14: =SUM(CO5:CO32) -> 3 | DT14: =SUM(CP5:CP32) -> 3 | DU14: =SUM(CQ5:CQ32) -> 2 | DV14: =SUM(CR5:CR32) -> 0 | ... EC14: =SUM(CY5:CY32) -> 2 | ED14: Total | EF14: =VLOOKUP(J14,MATERIAL,9,FALSE()) -> 0 | EG14: =VLOOKUP(K14,MATERIAL,9,FALSE()) -> 0 | EH14: =VLOOKUP(L14,MATERIAL,9,FALSE()) -> 0 | EI14: =VLOOKUP(M14,MATERIAL,9,FALSE()) -> 0 | EJ14: =VLOOKUP(N14,MATERIAL,9,FALSE()) -> 0 | EK14: =VLOOKUP(O14,MATERIAL,9,FALSE()) -> 0 | EL14: =VLOOKUP(P14,MATERIAL,9,FALSE()) -> 0 | EM14: =VLOOKUP(Q14,MATERIAL,9,FALSE()) -> 0 | ... ET14: =VLOOKUP(X14,MATERIAL,9,FALSE()) -> 0 | EU14: =IF($B14="",0,VLOOKUP($B14,ITEMS,EU$2,FALSE())) -> 0 | EV14: =VLOOKUP(EU14,MWS,2) -> 0 | EW14: =VLOOKUP(EU14,MWS,3) -> 0
